Workbook

Sheet Opening
A1: SKU | B1: Product | C1: Qty | D1: UnitCost | E1: ListPrice | F1: ReorderPoint | G1: ReorderQty
A2: TENT-2P | B2: Two-person tent | C2: 40 | D2: 88 | E2: 189 | F2: 15 | G2: 40
A3: TENT-4P | B3: Four-person tent | C3: 18 | D3: 142.5 | E3: 299 | F3: 8 | G3: 20
A4: BAG-SUM | B4: Summer sleeping bag | C4: 60 | D4: 31.25 | E4: 69 | F4: 20 | G4: 60
A5: BAG-WIN | B5: Winter sleeping bag | C5: 25 | D5: 74 | E5: 159 | F5: 10 | G5: 30
A6: PAD-FOAM | B6: Foam sleeping pad | C6: 80 | D6: 9.4 | E6: 24 | F6: 30 | G6: 80
A7: STOVE-GAS | B7: Gas camp stove | C7: 35 | D7: 27.8 | E7: 59 | F7: 12 | G7: 36
A8: LAMP-LED | B8: LED lantern | C8: 90 | D8: 11.6 | E8: 29 | F8: 30 | G8: 100
A9: PACK-35 | B9: 35 L daypack | C9: 45 | D9: 36 | E9: 79 | F9: 15 | G9: 40
A10: PACK-65 | B10: 65 L trekking pack | C10: 20 | D10: 97 | E10: 219 | F10: 8 | G10: 20
A11: BOTTLE-1L | B11: 1 L steel bottle | C11: 150 | D11: 6.1 | E11: 18 | F11: 50 | G11: 150
A12: CHAIR-FLD | B12: Folding camp chair | C12: 30 | D12: 22.4 | E12: 49 | F12: 12 | G12: 30
A13: FILTER-H2O | B13: Water filter | C13: 28 | D13: 41 | E13: 89 | F13: 10 | G13: 24

Sheet Transactions
A1: TxnID | B1: Date | C1: Type | D1: SKU | E1: Qty | F1: UnitCost | G1: UnitPrice | H1: Condition | I1: Category | J1: Amount | K1: Note
A2: T1001 | B2: 45839 | C2: SALE | D2: TENT-4P | E2: 1 | G2: 299
A3: T1002 | B3: 45839 | C3: SALE | D3: PACK-35 | E3: 3 | G3: 79
A4: T1004 | B4: 45839 | C4: EXPENSE | I4: Rent | J4: 3200
A5: T0999 | B5: 45840 | C5: RETURN | D5: FILTER-H2O | E5: 1 | G5: 89 | H5: resellable
A6: T1006 | B6: 45840 | C6: SALE | D6: BAG-SUM | E6: 8 | G6: 69
A7: T1007 | B7: 45840 | C7: SALE | D7: LAMP-LED | E7: 4 | G7: 29
A8: T1008 | B8: 45840 | C8: SALE | D8: PACK-65 | E8: 1 | G8: 197.1
A9: T1010 | B9: 45840 | C9: SALE | D9: FILTER-H2O | E9: 2 | G9: 89
A10: T1011 | B10: 45841 | C10: SALE | D10: TENT-2P | E10: 3 | G10: 170.1
A11: T1012 | B11: 45841 | C11: SALE | D11: BAG-SUM | E11: 3 | G11: 69
A12: T1013 | B12: 45841 | C12: SALE | D12: PACK-35 | E12: 3 | G12: 71.1
A13: T1014 | B13: 45841 | C13: SALE | D13: PACK-65 | E13: 6 | G13: 219
A14: T1015 | B14: 45842 | C14: SALE | D14: TENT-2P | E14: 2 | G14: 170.1
A15: T1016 | B15: 45842 | C15: SALE | D15: BAG-WIN | E15: 1 | G15: 135.15
A16: T1018 | B16: 45842 | C16: SALE | D16: LAMP-LED | E16: 4 | G16: 29
A17: T1019 | B17: 45842 | C17: SALE | D17: PACK-65 | E17: 4 | G17: 219
A18: T1020 | B18: 45842 | C18: SALE | D18: CHAIR-FLD | E18: 1 | G18: 44.1
A19: T1021 | B19: 45842 | C19: EXPENSE | I19: Shipping | J19: 343.9
A20: T1022 | B20: 45843 | C20: SALE | D20: TENT-2P | E20: 3 | G20: 189
A21: T1023 | B21: 45843 | C21: SALE | D21: TENT-4P | E21: 2 | G21: 254.15
A22: T1024 | B22: 45843 | C22: SALE | D22: LAMP-LED | E22: 8 | G22: 29
A23: T1025 | B23: 45843 | C23: SALE | D23: PACK-35 | E23: 3 | G23: 79
A24: T1026 | B24: 45843 | C24: SALE | D24: CHAIR-FLD | E24: 1 | G24: 41.65
A25: T1027 | B25: 45844 | C25: SALE | D25: TENT-4P | E25: 2 | G25: 269.1
A26: T1028 | B26: 45844 | C26: SALE | D26: PAD-FOAM | E26: 8 | G26: 24
A27: T1029 | B27: 45844 | C27: SALE | D27: STOVE-GAS | E27: 1 | G27: 50.15
A28: T1030 | B28: 45844 | C28: SALE | D28: LAMP-LED | E28: 4 | G28: 29
A29: T1031 | B29: 45844 | C29: SALE | D29: CHAIR-FLD | E29: 4 | G29: 44.1
A30: T1033 | B30: 45844 | C30: RECEIPT | D30: BOTTLE-1L | E30: 150 | F30: 6.1
A31: T1035 | B31: 45844 | C31: RETURN | D31: PAD-FOAM | E31: 1 | G31: 24 | H31: resellable
A32: T1036 | B32: 45845 | C32: SALE | D32: TENT-2P | E32: 1 | G32: 189
A33: T1038 | B33: 45845 | C33: SALE | D33: PAD-FOAM | E33: 4 | G33: 24
A34: T1039 | B34: 45845 | C34: SALE | D34: PACK-35 | E34: 3 | G34: 79
A35: T1040 | B35: 45845 | C35: SALE | D35: BOTTLE-1L | E35: 4 | G35: 18
A36: T1042 | B36: 45845 | C36: SALE | D36: CHAIR-FLD | E36: 4 | G36: 41.65
A37: T1044 | B37: 45845 | C37: SALE | D37: FILTER-H2O | E37: 1 | G37: 80.1
A38: T1045 | B38: 45845 | C38: RECEIPT | D38: TENT-2P | E38: 40 | F38: 88
A39: T1047 | B39: 45846 | C39: SALE | D39: TENT-4P | E39: 2 | G39: 299
A40: T1048 | B40: 45846 | C40: SALE | D40: PAD-FOAM | E40: 8 | G40: 20.4
...

Sheet Calc
A1: SKU | B1: Type | C1: Month | D1: Dup | E1: Valid | F1: SupplyQty | G1: SupplyCost | H1: RcptRow | I1: DemandQty | J1: SupplyBefore | K1: DemandBefore | L1: OpenQty | M1: Ship1 | N1: Ship2 | O1: Ship3 | P1: C0 | Q1: C1 | R1: C2 | S1: C3 | T1: Refund | U1: Opex | V1: ExcRow | W1: OpenCost
A2: =IF(Transactions!D2="","",UPPER(TRIM(Transactions!D2))) | B2: =IF(Transactions!C2="","",UPPER(TRIM(Transactions!C2))) | C2: =IF(Transactions!B2="",0,YEAR(Transactions!B2)*100+MONTH(Transactions!B2)) | D2: =IF(Transactions!A2="",1,IF(COUNTIF(Transactions!$A$1:A1,Transactions!A2)>0,1,0)) | E2: =IF(D2=1,0,IF(B2="RETURN",IF(COUNTIFS($A$1:A1,A2,$B$1:B1,"SALE",$E$1:E1,1)>0,1,0),1)) | F2: =IF(E2=1,IF(B2="RECEIPT",Transactions!E2,IF(AND(B2="RETURN",LOWER(TRIM(Transactions!H2))="resellable"),Transactions!E2,0)),0) | G2: =IF(F2>0,IF(B2="RECEIPT",Transactions!F2,IF(_xlfn.MAXIFS($H$2:H2,$A$2:A2,A2)>0,INDEX(Transactions!$F:$F,_xlfn.MAXIFS($H$2:H2,$A$2:A2,A2)),W2)),0) | H2: =IF(AND(E2=1,B2="RECEIPT"),ROW(),0) | I2: =IF(E2=1,IF(OR(B2="SALE",B2="WRITEOFF"),Transactions!E2,0),0) | J2: =SUMIFS($F$1:F1,$A$1:A1,A2) | K2: =SUMIFS($I$1:I1,$A$1:A1,A2) | L2: =IFERROR(VLOOKUP(A2,Opening!$A:$C,3,0),0) | M2: =IF(I2=0,0,MAX(0,MIN(INDEX(Month!H$2:H$13,MATCH($A2,Month!$A$2:$A$13,0))-K2,I2))) | N2: =IF(I2=0,0,MAX(0,MIN(INDEX(Month!I$2:I$13,MATCH($A2,Month!$A$2:$A$13,0))-K2,I2))) | O2: =IF(I2=0,0,MAX(0,MIN(INDEX(Month!J$2:J$13,MATCH($A2,Month!$A$2:$A$13,0))-K2,I2))) | P2: =IF(I2=0,0,(MIN(MAX(K2,0),L2)*W2+SUMPRODUCT((Calc!$A$2:$A$1001=A2)*Calc!$G$2:$G$1001*(((K2-(L2+Calc!$J$2:$J$1001))>0)*((K2-(L2+Calc!$J$2:$J$1001))<Calc!$F$2:$F$1001)*(K2-(L2+Calc!$J$2:$J$1001))+((K2-(L2+Calc!$J$2:$J$1001))>=Calc!$F$2:$F$1001)*Calc!$F$2:$F$1001)))) | Q2: =IF(I2=0,0,(MIN(MAX((K2+M2),0),L2)*W2+SUMPRODUCT((Calc!$A$2:$A$1001=A2)*Calc!$G$2:$G$1001*((((K2+M2)-(L2+Calc!$J$2:$J$1001))>0)*(((K2+M2)-(L2+Calc!$J$2:$J$1001))<Calc!$F$2:$F$1001)*((K2+M2)-(L2+Calc!$J$2:$J$1001))+(((K2+M2)-(L2+Calc!$J$2:$J$1001))>=Calc!$F$2:$F$1001)*Calc!$F$2:$F$1001)))) | R2: =IF(I2=0,0,(MIN(MAX((K2+N2),0),L2)*W2+SUMPRODUCT((Calc!$A$2:$A$1001=A2)*Calc!$G$2:$G$1001*((((K2+N2)-(L2+Calc!$J$2:$J$1001))>0)*(((K2+N2)-(L2+Calc!$J$2:$J$1001))<Calc!$F$2:$F$1001)*((K2+N2)-(L2+Calc!$J$2:$J$1001))+(((K2+N2)-(L2+Calc!$J$2:$J$1001))>=Calc!$F$2:$F$1001)*Calc!$F$2:$F$1001)))) | S2: =IF(I2=0,0,(MIN(MAX((K2+O2),0),L2)*W2+SUMPRODUCT((Calc!$A$2:$A$1001=A2)*Calc!$G$2:$G$1001*((((K2+O2)-(L2+Calc!$J$2:$J$1001))>0)*(((K2+O2)-(L2+Calc!$J$2:$J$1001))<Calc!$F$2:$F$1001)*((K2+O2)-(L2+Calc!$J$2:$J$1001))+(((K2+O2)-(L2+Calc!$J$2:$J$1001))>=Calc!$F$2:$F$1001)*Calc!$F$2:$F$1001)))) | T2: =IF(AND(E2=1,B2="RETURN"),Transactions!E2*Transactions!G2,0) | U2: =IF(AND(E2=1,B2="EXPENSE"),Transactions!J2,0) | V2: =IF(AND(Transactions!A2<>"",E2=0),ROW(),"") | W2: =IFERROR(VLOOKUP(A2,Opening!$A:$D,4,0),0)
A3: =IF(Transactions!D3="","",UPPER(TRIM(Transactions!D3))) | B3: =IF(Transactions!C3="","",UPPER(TRIM(Transactions!C3))) | C3: =IF(Transactions!B3="",0,YEAR(Transactions!B3)*100+MONTH(Transactions!B3)) | D3: =IF(Transactions!A3="",1,IF(COUNTIF(Transactions!$A$1:A2,Transactions!A3)>0,1,0)) | E3: =IF(D3=1,0,IF(B3="RETURN",IF(COUNTIFS($A$1:A2,A3,$B$1:B2,"SALE",$E$1:E2,1)>0,1,0),1)) | F3: =IF(E3=1,IF(B3="RECEIPT",Transactions!E3,IF(AND(B3="RETURN",LOWER(TRIM(Transactions!H3))="resellable"),Transactions!E3,0)),0) | G3: =IF(F3>0,IF(B3="RECEIPT",Transactions!F3,IF(_xlfn.MAXIFS($H$2:H3,$A$2:A3,A3)>0,INDEX(Transactions!$F:$F,_xlfn.MAXIFS($H$2:H3,$A$2:A3,A3)),W3)),0) | H3: =IF(AND(E3=1,B3="RECEIPT"),ROW(),0) | I3: =IF(E3=1,IF(OR(B3="SALE",B3="WRITEOFF"),Transactions!E3,0),0) | J3: =SUMIFS($F$1:F2,$A$1:A2,A3) | K3: =SUMIFS($I$1:I2,$A$1:A2,A3) | L3: =IFERROR(VLOOKUP(A3,Opening!$A:$C,3,0),0) | M3: =IF(I3=0,0,MAX(0,MIN(INDEX(Month!H$2:H$13,MATCH($A3,Month!$A$2:$A$13,0))-K3,I3))) | N3: =IF(I3=0,0,MAX(0,MIN(INDEX(Month!I$2:I$13,MATCH($A3,Month!$A$2:$A$13,0))-K3,I3))) | O3: =IF(I3=0,0,MAX(0,MIN(INDEX(Month!J$2:J$13,MATCH($A3,Month!$A$2:$A$13,0))-K3,I3))) | P3: =IF(I3=0,0,(MIN(MAX(K3,0),L3)*W3+SUMPRODUCT((Calc!$A$2:$A$1001=A3)*Calc!$G$2:$G$1001*(((K3-(L3+Calc!$J$2:$J$1001))>0)*((K3-(L3+Calc!$J$2:$J$1001))<Calc!$F$2:$F$1001)*(K3-(L3+Calc!$J$2:$J$1001))+((K3-(L3+Calc!$J$2:$J$1001))>=Calc!$F$2:$F$1001)*Calc!$F$2:$F$1001)))) | Q3: =IF(I3=0,0,(MIN(MAX((K3+M3),0),L3)*W3+SUMPRODUCT((Calc!$A$2:$A$1001=A3)*Calc!$G$2:$G$1001*((((K3+M3)-(L3+Calc!$J$2:$J$1001))>0)*(((K3+M3)-(L3+Calc!$J$2:$J$1001))<Calc!$F$2:$F$1001)*((K3+M3)-(L3+Calc!$J$2:$J$1001))+(((K3+M3)-(L3+Calc!$J$2:$J$1001))>=Calc!$F$2:$F$1001)*Calc!$F$2:$F$1001)))) | R3: =IF(I3=0,0,(MIN(MAX((K3+N3),0),L3)*W3+SUMPRODUCT((Calc!$A$2:$A$1001=A3)*Calc!$G$2:$G$1001*((((K3+N3)-(L3+Calc!$J$2:$J$1001))>0)*(((K3+N3)-(L3+Calc!$J$2:$J$1001))<Calc!$F$2:$F$1001)*((K3+N3)-(L3+Calc!$J$2:$J$1001))+(((K3+N3)-(L3+Calc!$J$2:$J$1001))>=Calc!$F$2:$F$1001)*Calc!$F$2:$F$1001)))) | S3: =IF(I3=0,0,(MIN(MAX((K3+O3),0),L3)*W3+SUMPRODUCT((Calc!$A$2:$A$1001=A3)*Calc!$G$2:$G$1001*((((K3+O3)-(L3+Calc!$J$2:$J$1001))>0)*(((K3+O3)-(L3+Calc!$J$2:$J$1001))<Calc!$F$2:$F$1001)*((K3+O3)-(L3+Calc!$J$2:$J$1001))+(((K3+O3)-(L3+Calc!$J$2:$J$1001))>=Calc!$F$2:$F$1001)*Calc!$F$2:$F$1001)))) | T3: =IF(AND(E3=1,B3="RETURN"),Transactions!E3*Transactions!G3,0) | U3: =IF(AND(E3=1,B3="EXPENSE"),Transactions!J3,0) | V3: =IF(AND(Transactions!A3<>"",E3=0),ROW(),"") | W3: =IFERROR(VLOOKUP(A3,Opening!$A:$D,4,0),0)
A4: =IF(Transactions!D4="","",UPPER(TRIM(Transactions!D4))) | B4: =IF(Transactions!C4="","",UPPER(TRIM(Transactions!C4))) | C4: =IF(Transactions!B4="",0,YEAR(Transactions!B4)*100+MONTH(Transactions!B4)) | D4: =IF(Transactions!A4="",1,IF(COUNTIF(Transactions!$A$1:A3,Transactions!A4)>0,1,0)) | E4: =IF(D4=1,0,IF(B4="RETURN",IF(COUNTIFS($A$1:A3,A4,$B$1:B3,"SALE",$E$1:E3,1)>0,1,0),1)) | F4: =IF(E4=1,IF(B4="RECEIPT",Transactions!E4,IF(AND(B4="RETURN",LOWER(TRIM(Transactions!H4))="resellable"),Transactions!E4,0)),0) | G4: =IF(F4>0,IF(B4="RECEIPT",Transactions!F4,IF(_xlfn.MAXIFS($H$2:H4,$A$2:A4,A4)>0,INDEX(Transactions!$F:$F,_xlfn.MAXIFS($H$2:H4,$A$2:A4,A4)),W4)),0) | H4: =IF(AND(E4=1,B4="RECEIPT"),ROW(),0) | I4: =IF(E4=1,IF(OR(B4="SALE",B4="WRITEOFF"),Transactions!E4,0),0) | J4: =SUMIFS($F$1:F3,$A$1:A3,A4) | K4: =SUMIFS($I$1:I3,$A$1:A3,A4) | L4: =IFERROR(VLOOKUP(A4,Opening!$A:$C,3,0),0) | M4: =IF(I4=0,0,MAX(0,MIN(INDEX(Month!H$2:H$13,MATCH($A4,Month!$A$2:$A$13,0))-K4,I4))) | N4: =IF(I4=0,0,MAX(0,MIN(INDEX(Month!I$2:I$13,MATCH($A4,Month!$A$2:$A$13,0))-K4,I4))) | O4: =IF(I4=0,0,MAX(0,MIN(INDEX(Month!J$2:J$13,MATCH($A4,Month!$A$2:$A$13,0))-K4,I4))) | P4: =IF(I4=0,0,(MIN(MAX(K4,0),L4)*W4+SUMPRODUCT((Calc!$A$2:$A$1001=A4)*Calc!$G$2:$G$1001*(((K4-(L4+Calc!$J$2:$J$1001))>0)*((K4-(L4+Calc!$J$2:$J$1001))<Calc!$F$2:$F$1001)*(K4-(L4+Calc!$J$2:$J$1001))+((K4-(L4+Calc!$J$2:$J$1001))>=Calc!$F$2:$F$1001)*Calc!$F$2:$F$1001)))) | Q4: =IF(I4=0,0,(MIN(MAX((K4+M4),0),L4)*W4+SUMPRODUCT((Calc!$A$2:$A$1001=A4)*Calc!$G$2:$G$1001*((((K4+M4)-(L4+Calc!$J$2:$J$1001))>0)*(((K4+M4)-(L4+Calc!$J$2:$J$1001))<Calc!$F$2:$F$1001)*((K4+M4)-(L4+Calc!$J$2:$J$1001))+(((K4+M4)-(L4+Calc!$J$2:$J$1001))>=Calc!$F$2:$F$1001)*Calc!$F$2:$F$1001)))) | R4: =IF(I4=0,0,(MIN(MAX((K4+N4),0),L4)*W4+SUMPRODUCT((Calc!$A$2:$A$1001=A4)*Calc!$G$2:$G$1001*((((K4+N4)-(L4+Calc!$J$2:$J$1001))>0)*(((K4+N4)-(L4+Calc!$J$2:$J$1001))<Calc!$F$2:$F$1001)*((K4+N4)-(L4+Calc!$J$2:$J$1001))+(((K4+N4)-(L4+Calc!$J$2:$J$1001))>=Calc!$F$2:$F$1001)*Calc!$F$2:$F$1001)))) | S4: =IF(I4=0,0,(MIN(MAX((K4+O4),0),L4)*W4+SUMPRODUCT((Calc!$A$2:$A$1001=A4)*Calc!$G$2:$G$1001*((((K4+O4)-(L4+Calc!$J$2:$J$1001))>0)*(((K4+O4)-(L4+Calc!$J$2:$J$1001))<Calc!$F$2:$F$1001)*((K4+O4)-(L4+Calc!$J$2:$J$1001))+(((K4+O4)-(L4+Calc!$J$2:$J$1001))>=Calc!$F$2:$F$1001)*Calc!$F$2:$F$1001)))) | T4: =IF(AND(E4=1,B4="RETURN"),Transactions!E4*Transactions!G4,0) | U4: =IF(AND(E4=1,B4="EXPENSE"),Transactions!J4,0) | V4: =IF(AND(Transactions!A4<>"",E4=0),ROW(),"") | W4: =IFERROR(VLOOKUP(A4,Opening!$A:$D,4,0),0)
A5: =IF(Transactions!D5="","",UPPER(TRIM(Transactions!D5))) | B5: =IF(Transactions!C5="","",UPPER(TRIM(Transactions!C5))) | C5: =IF(Transactions!B5="",0,YEAR(Transactions!B5)*100+MONTH(Transactions!B5)) | D5: =IF(Transactions!A5="",1,IF(COUNTIF(Transactions!$A$1:A4,Transactions!A5)>0,1,0)) | E5: =IF(D5=1,0,IF(B5="RETURN",IF(COUNTIFS($A$1:A4,A5,$B$1:B4,"SALE",$E$1:E4,1)>0,1,0),1)) | F5: =IF(E5=1,IF(B5="RECEIPT",Transactions!E5,IF(AND(B5="RETURN",LOWER(TRIM(Transactions!H5))="resellable"),Transactions!E5,0)),0) | G5: =IF(F5>0,IF(B5="RECEIPT",Transactions!F5,IF(_xlfn.MAXIFS($H$2:H5,$A$2:A5,A5)>0,INDEX(Transactions!$F:$F,_xlfn.MAXIFS($H$2:H5,$A$2:A5,A5)),W5)),0) | H5: =IF(AND(E5=1,B5="RECEIPT"),ROW(),0) | I5: =IF(E5=1,IF(OR(B5="SALE",B5="WRITEOFF"),Transactions!E5,0),0) | J5: =SUMIFS($F$1:F4,$A$1:A4,A5) | K5: =SUMIFS($I$1:I4,$A$1:A4,A5) | L5: =IFERROR(VLOOKUP(A5,Opening!$A:$C,3,0),0) | M5: =IF(I5=0,0,MAX(0,MIN(INDEX(Month!H$2:H$13,MATCH($A5,Month!$A$2:$A$13,0))-K5,I5))) | N5: =IF(I5=0,0,MAX(0,MIN(INDEX(Month!I$2:I$13,MATCH($A5,Month!$A$2:$A$13,0))-K5,I5))) | O5: =IF(I5=0,0,MAX(0,MIN(INDEX(Month!J$2:J$13,MATCH($A5,Month!$A$2:$A$13,0))-K5,I5))) | P5: =IF(I5=0,0,(MIN(MAX(K5,0),L5)*W5+SUMPRODUCT((Calc!$A$2:$A$1001=A5)*Calc!$G$2:$G$1001*(((K5-(L5+Calc!$J$2:$J$1001))>0)*((K5-(L5+Calc!$J$2:$J$1001))<Calc!$F$2:$F$1001)*(K5-(L5+Calc!$J$2:$J$1001))+((K5-(L5+Calc!$J$2:$J$1001))>=Calc!$F$2:$F$1001)*Calc!$F$2:$F$1001)))) | Q5: =IF(I5=0,0,(MIN(MAX((K5+M5),0),L5)*W5+SUMPRODUCT((Calc!$A$2:$A$1001=A5)*Calc!$G$2:$G$1001*((((K5+M5)-(L5+Calc!$J$2:$J$1001))>0)*(((K5+M5)-(L5+Calc!$J$2:$J$1001))<Calc!$F$2:$F$1001)*((K5+M5)-(L5+Calc!$J$2:$J$1001))+(((K5+M5)-(L5+Calc!$J$2:$J$1001))>=Calc!$F$2:$F$1001)*Calc!$F$2:$F$1001)))) | R5: =IF(I5=0,0,(MIN(MAX((K5+N5),0),L5)*W5+SUMPRODUCT((Calc!$A$2:$A$1001=A5)*Calc!$G$2:$G$1001*((((K5+N5)-(L5+Calc!$J$2:$J$1001))>0)*(((K5+N5)-(L5+Calc!$J$2:$J$1001))<Calc!$F$2:$F$1001)*((K5+N5)-(L5+Calc!$J$2:$J$1001))+(((K5+N5)-(L5+Calc!$J$2:$J$1001))>=Calc!$F$2:$F$1001)*Calc!$F$2:$F$1001)))) | S5: =IF(I5=0,0,(MIN(MAX((K5+O5),0),L5)*W5+SUMPRODUCT((Calc!$A$2:$A$1001=A5)*Calc!$G$2:$G$1001*((((K5+O5)-(L5+Calc!$J$2:$J$1001))>0)*(((K5+O5)-(L5+Calc!$J$2:$J$1001))<Calc!$F$2:$F$1001)*((K5+O5)-(L5+Calc!$J$2:$J$1001))+(((K5+O5)-(L5+Calc!$J$2:$J$1001))>=Calc!$F$2:$F$1001)*Calc!$F$2:$F$1001)))) | T5: =IF(AND(E5=1,B5="RETURN"),Transactions!E5*Transactions!G5,0) | U5: =IF(AND(E5=1,B5="EXPENSE"),Transactions!J5,0) | V5: =IF(AND(Transactions!A5<>"",E5=0),ROW(),"") | W5: =IFERROR(VLOOKUP(A5,Opening!$A:$D,4,0),0)
A6: =IF(Transactions!D6="","",UPPER(TRIM(Transactions!D6))) | B6: =IF(Transactions!C6="","",UPPER(TRIM(Transactions!C6))) | C6: =IF(Transactions!B6="",0,YEAR(Transactions!B6)*100+MONTH(Transactions!B6)) | D6: =IF(Transactions!A6="",1,IF(COUNTIF(Transactions!$A$1:A5,Transactions!A6)>0,1,0)) | E6: =IF(D6=1,0,IF(B6="RETURN",IF(COUNTIFS($A$1:A5,A6,$B$1:B5,"SALE",$E$1:E5,1)>0,1,0),1)) | F6: =IF(E6=1,IF(B6="RECEIPT",Transactions!E6,IF(AND(B6="RETURN",LOWER(TRIM(Transactions!H6))="resellable"),Transactions!E6,0)),0) | G6: =IF(F6>0,IF(B6="RECEIPT",Transactions!F6,IF(_xlfn.MAXIFS($H$2:H6,$A$2:A6,A6)>0,INDEX(Transactions!$F:$F,_xlfn.MAXIFS($H$2:H6,$A$2:A6,A6)),W6)),0) | H6: =IF(AND(E6=1,B6="RECEIPT"),ROW(),0) | I6: =IF(E6=1,IF(OR(B6="SALE",B6="WRITEOFF"),Transactions!E6,0),0) | J6: =SUMIFS($F$1:F5,$A$1:A5,A6) | K6: =SUMIFS($I$1:I5,$A$1:A5,A6) | L6: =IFERROR(VLOOKUP(A6,Opening!$A:$C,3,0),0) | M6: =IF(I6=0,0,MAX(0,MIN(INDEX(Month!H$2:H$13,MATCH($A6,Month!$A$2:$A$13,0))-K6,I6))) | N6: =IF(I6=0,0,MAX(0,MIN(INDEX(Month!I$2:I$13,MATCH($A6,Month!$A$2:$A$13,0))-K6,I6))) | O6: =IF(I6=0,0,MAX(0,MIN(INDEX(Month!J$2:J$13,MATCH($A6,Month!$A$2:$A$13,0))-K6,I6))) | P6: =IF(I6=0,0,(MIN(MAX(K6,0),L6)*W6+SUMPRODUCT((Calc!$A$2:$A$1001=A6)*Calc!$G$2:$G$1001*(((K6-(L6+Calc!$J$2:$J$1001))>0)*((K6-(L6+Calc!$J$2:$J$1001))<Calc!$F$2:$F$1001)*(K6-(L6+Calc!$J$2:$J$1001))+((K6-(L6+Calc!$J$2:$J$1001))>=Calc!$F$2:$F$1001)*Calc!$F$2:$F$1001)))) | Q6: =IF(I6=0,0,(MIN(MAX((K6+M6),0),L6)*W6+SUMPRODUCT((Calc!$A$2:$A$1001=A6)*Calc!$G$2:$G$1001*((((K6+M6)-(L6+Calc!$J$2:$J$1001))>0)*(((K6+M6)-(L6+Calc!$J$2:$J$1001))<Calc!$F$2:$F$1001)*((K6+M6)-(L6+Calc!$J$2:$J$1001))+(((K6+M6)-(L6+Calc!$J$2:$J$1001))>=Calc!$F$2:$F$1001)*Calc!$F$2:$F$1001)))) | R6: =IF(I6=0,0,(MIN(MAX((K6+N6),0),L6)*W6+SUMPRODUCT((Calc!$A$2:$A$1001=A6)*Calc!$G$2:$G$1001*((((K6+N6)-(L6+Calc!$J$2:$J$1001))>0)*(((K6+N6)-(L6+Calc!$J$2:$J$1001))<Calc!$F$2:$F$1001)*((K6+N6)-(L6+Calc!$J$2:$J$1001))+(((K6+N6)-(L6+Calc!$J$2:$J$1001))>=Calc!$F$2:$F$1001)*Calc!$F$2:$F$1001)))) | S6: =IF(I6=0,0,(MIN(MAX((K6+O6),0),L6)*W6+SUMPRODUCT((Calc!$A$2:$A$1001=A6)*Calc!$G$2:$G$1001*((((K6+O6)-(L6+Calc!$J$2:$J$1001))>0)*(((K6+O6)-(L6+Calc!$J$2:$J$1001))<Calc!$F$2:$F$1001)*((K6+O6)-(L6+Calc!$J$2:$J$1001))+(((K6+O6)-(L6+Calc!$J$2:$J$1001))>=Calc!$F$2:$F$1001)*Calc!$F$2:$F$1001)))) | T6: =IF(AND(E6=1,B6="RETURN"),Transactions!E6*Transactions!G6,0) | U6: =IF(AND(E6=1,B6="EXPENSE"),Transactions!J6,0) | V6: =IF(AND(Transactions!A6<>"",E6=0),ROW(),"") | W6: =IFERROR(VLOOKUP(A6,Opening!$A:$D,4,0),0)
A7: =IF(Transactions!D7="","",UPPER(TRIM(Transactions!D7))) | B7: =IF(Transactions!C7="","",UPPER(TRIM(Transactions!C7))) | C7: =IF(Transactions!B7="",0,YEAR(Transactions!B7)*100+MONTH(Transactions!B7)) | D7: =IF(Transactions!A7="",1,IF(COUNTIF(Transactions!$A$1:A6,Transactions!A7)>0,1,0)) | E7: =IF(D7=1,0,IF(B7="RETURN",IF(COUNTIFS($A$1:A6,A7,$B$1:B6,"SALE",$E$1:E6,1)>0,1,0),1)) | F7: =IF(E7=1,IF(B7="RECEIPT",Transactions!E7,IF(AND(B7="RETURN",LOWER(TRIM(Transactions!H7))="resellable"),Transactions!E7,0)),0) | G7: =IF(F7>0,IF(B7="RECEIPT",Transactions!F7,IF(_xlfn.MAXIFS($H$2:H7,$A$2:A7,A7)>0,INDEX(Transactions!$F:$F,_xlfn.MAXIFS($H$2:H7,$A$2:A7,A7)),W7)),0) | H7: =IF(AND(E7=1,B7="RECEIPT"),ROW(),0) | I7: =IF(E7=1,IF(OR(B7="SALE",B7="WRITEOFF"),Transactions!E7,0),0) | J7: =SUMIFS($F$1:F6,$A$1:A6,A7) | K7: =SUMIFS($I$1:I6,$A$1:A6,A7) | L7: =IFERROR(VLOOKUP(A7,Opening!$A:$C,3,0),0) | M7: =IF(I7=0,0,MAX(0,MIN(INDEX(Month!H$2:H$13,MATCH($A7,Month!$A$2:$A$13,0))-K7,I7))) | N7: =IF(I7=0,0,MAX(0,MIN(INDEX(Month!I$2:I$13,MATCH($A7,Month!$A$2:$A$13,0))-K7,I7))) | O7: =IF(I7=0,0,MAX(0,MIN(INDEX(Month!J$2:J$13,MATCH($A7,Month!$A$2:$A$13,0))-K7,I7))) | P7: =IF(I7=0,0,(MIN(MAX(K7,0),L7)*W7+SUMPRODUCT((Calc!$A$2:$A$1001=A7)*Calc!$G$2:$G$1001*(((K7-(L7+Calc!$J$2:$J$1001))>0)*((K7-(L7+Calc!$J$2:$J$1001))<Calc!$F$2:$F$1001)*(K7-(L7+Calc!$J$2:$J$1001))+((K7-(L7+Calc!$J$2:$J$1001))>=Calc!$F$2:$F$1001)*Calc!$F$2:$F$1001)))) | Q7: =IF(I7=0,0,(MIN(MAX((K7+M7),0),L7)*W7+SUMPRODUCT((Calc!$A$2:$A$1001=A7)*Calc!$G$2:$G$1001*((((K7+M7)-(L7+Calc!$J$2:$J$1001))>0)*(((K7+M7)-(L7+Calc!$J$2:$J$1001))<Calc!$F$2:$F$1001)*((K7+M7)-(L7+Calc!$J$2:$J$1001))+(((K7+M7)-(L7+Calc!$J$2:$J$1001))>=Calc!$F$2:$F$1001)*Calc!$F$2:$F$1001)))) | R7: =IF(I7=0,0,(MIN(MAX((K7+N7),0),L7)*W7+SUMPRODUCT((Calc!$A$2:$A$1001=A7)*Calc!$G$2:$G$1001*((((K7+N7)-(L7+Calc!$J$2:$J$1001))>0)*(((K7+N7)-(L7+Calc!$J$2:$J$1001))<Calc!$F$2:$F$1001)*((K7+N7)-(L7+Calc!$J$2:$J$1001))+(((K7+N7)-(L7+Calc!$J$2:$J$1001))>=Calc!$F$2:$F$1001)*Calc!$F$2:$F$1001)))) | S7: =IF(I7=0,0,(MIN(MAX((K7+O7),0),L7)*W7+SUMPRODUCT((Calc!$A$2:$A$1001=A7)*Calc!$G$2:$G$1001*((((K7+O7)-(L7+Calc!$J$2:$J$1001))>0)*(((K7+O7)-(L7+Calc!$J$2:$J$1001))<Calc!$F$2:$F$1001)*((K7+O7)-(L7+Calc!$J$2:$J$1001))+(((K7+O7)-(L7+Calc!$J$2:$J$1001))>=Calc!$F$2:$F$1001)*Calc!$F$2:$F$1001)))) | T7: =IF(AND(E7=1,B7="RETURN"),Transactions!E7*Transactions!G7,0) | U7: =IF(AND(E7=1,B7="EXPENSE"),Transactions!J7,0) | V7: =IF(AND(Transactions!A7<>"",E7=0),ROW(),"") | W7: =IFERROR(VLOOKUP(A7,Opening!$A:$D,4,0),0)
A8: =IF(Transactions!D8="","",UPPER(TRIM(Transactions!D8))) | B8: =IF(Transactions!C8="","",UPPER(TRIM(Transactions!C8))) | C8: =IF(Transactions!B8="",0,YEAR(Transactions!B8)*100+MONTH(Transactions!B8)) | D8: =IF(Transactions!A8="",1,IF(COUNTIF(Transactions!$A$1:A7,Transactions!A8)>0,1,0)) | E8: =IF(D8=1,0,IF(B8="RETURN",IF(COUNTIFS($A$1:A7,A8,$B$1:B7,"SALE",$E$1:E7,1)>0,1,0),1)) | F8: =IF(E8=1,IF(B8="RECEIPT",Transactions!E8,IF(AND(B8="RETURN",LOWER(TRIM(Transactions!H8))="resellable"),Transactions!E8,0)),0) | G8: =IF(F8>0,IF(B8="RECEIPT",Transactions!F8,IF(_xlfn.MAXIFS($H$2:H8,$A$2:A8,A8)>0,INDEX(Transactions!$F:$F,_xlfn.MAXIFS($H$2:H8,$A$2:A8,A8)),W8)),0) | H8: =IF(AND(E8=1,B8="RECEIPT"),ROW(),0) | I8: =IF(E8=1,IF(OR(B8="SALE",B8="WRITEOFF"),Transactions!E8,0),0) | J8: =SUMIFS($F$1:F7,$A$1:A7,A8) | K8: =SUMIFS($I$1:I7,$A$1:A7,A8) | L8: =IFERROR(VLOOKUP(A8,Opening!$A:$C,3,0),0) | M8: =IF(I8=0,0,MAX(0,MIN(INDEX(Month!H$2:H$13,MATCH($A8,Month!$A$2:$A$13,0))-K8,I8))) | N8: =IF(I8=0,0,MAX(0,MIN(INDEX(Month!I$2:I$13,MATCH($A8,Month!$A$2:$A$13,0))-K8,I8))) | O8: =IF(I8=0,0,MAX(0,MIN(INDEX(Month!J$2:J$13,MATCH($A8,Month!$A$2:$A$13,0))-K8,I8))) | P8: =IF(I8=0,0,(MIN(MAX(K8,0),L8)*W8+SUMPRODUCT((Calc!$A$2:$A$1001=A8)*Calc!$G$2:$G$1001*(((K8-(L8+Calc!$J$2:$J$1001))>0)*((K8-(L8+Calc!$J$2:$J$1001))<Calc!$F$2:$F$1001)*(K8-(L8+Calc!$J$2:$J$1001))+((K8-(L8+Calc!$J$2:$J$1001))>=Calc!$F$2:$F$1001)*Calc!$F$2:$F$1001)))) | Q8: =IF(I8=0,0,(MIN(MAX((K8+M8),0),L8)*W8+SUMPRODUCT((Calc!$A$2:$A$1001=A8)*Calc!$G$2:$G$1001*((((K8+M8)-(L8+Calc!$J$2:$J$1001))>0)*(((K8+M8)-(L8+Calc!$J$2:$J$1001))<Calc!$F$2:$F$1001)*((K8+M8)-(L8+Calc!$J$2:$J$1001))+(((K8+M8)-(L8+Calc!$J$2:$J$1001))>=Calc!$F$2:$F$1001)*Calc!$F$2:$F$1001)))) | R8: =IF(I8=0,0,(MIN(MAX((K8+N8),0),L8)*W8+SUMPRODUCT((Calc!$A$2:$A$1001=A8)*Calc!$G$2:$G$1001*((((K8+N8)-(L8+Calc!$J$2:$J$1001))>0)*(((K8+N8)-(L8+Calc!$J$2:$J$1001))<Calc!$F$2:$F$1001)*((K8+N8)-(L8+Calc!$J$2:$J$1001))+(((K8+N8)-(L8+Calc!$J$2:$J$1001))>=Calc!$F$2:$F$1001)*Calc!$F$2:$F$1001)))) | S8: =IF(I8=0,0,(MIN(MAX((K8+O8),0),L8)*W8+SUMPRODUCT((Calc!$A$2:$A$1001=A8)*Calc!$G$2:$G$1001*((((K8+O8)-(L8+Calc!$J$2:$J$1001))>0)*(((K8+O8)-(L8+Calc!$J$2:$J$1001))<Calc!$F$2:$F$1001)*((K8+O8)-(L8+Calc!$J$2:$J$1001))+(((K8+O8)-(L8+Calc!$J$2:$J$1001))>=Calc!$F$2:$F$1001)*Calc!$F$2:$F$1001)))) | T8: =IF(AND(E8=1,B8="RETURN"),Transactions!E8*Transactions!G8,0) | U8: =IF(AND(E8=1,B8="EXPENSE"),Transactions!J8,0) | V8: =IF(AND(Transactions!A8<>"",E8=0),ROW(),"") | W8: =IFERROR(VLOOKUP(A8,Opening!$A:$D,4,0),0)
A9: =IF(Transactions!D9="","",UPPER(TRIM(Transactions!D9))) | B9: =IF(Transactions!C9="","",UPPER(TRIM(Transactions!C9))) | C9: =IF(Transactions!B9="",0,YEAR(Transactions!B9)*100+MONTH(Transactions!B9)) | D9: =IF(Transactions!A9="",1,IF(COUNTIF(Transactions!$A$1:A8,Transactions!A9)>0,1,0)) | E9: =IF(D9=1,0,IF(B9="RETURN",IF(COUNTIFS($A$1:A8,A9,$B$1:B8,"SALE",$E$1:E8,1)>0,1,0),1)) | F9: =IF(E9=1,IF(B9="RECEIPT",Transactions!E9,IF(AND(B9="RETURN",LOWER(TRIM(Transactions!H9))="resellable"),Transactions!E9,0)),0) | G9: =IF(F9>0,IF(B9="RECEIPT",Transactions!F9,IF(_xlfn.MAXIFS($H$2:H9,$A$2:A9,A9)>0,INDEX(Transactions!$F:$F,_xlfn.MAXIFS($H$2:H9,$A$2:A9,A9)),W9)),0) | H9: =IF(AND(E9=1,B9="RECEIPT"),ROW(),0) | I9: =IF(E9=1,IF(OR(B9="SALE",B9="WRITEOFF"),Transactions!E9,0),0) | J9: =SUMIFS($F$1:F8,$A$1:A8,A9) | K9: =SUMIFS($I$1:I8,$A$1:A8,A9) | L9: =IFERROR(VLOOKUP(A9,Opening!$A:$C,3,0),0) | M9: =IF(I9=0,0,MAX(0,MIN(INDEX(Month!H$2:H$13,MATCH($A9,Month!$A$2:$A$13,0))-K9,I9))) | N9: =IF(I9=0,0,MAX(0,MIN(INDEX(Month!I$2:I$13,MATCH($A9,Month!$A$2:$A$13,0))-K9,I9))) | O9: =IF(I9=0,0,MAX(0,MIN(INDEX(Month!J$2:J$13,MATCH($A9,Month!$A$2:$A$13,0))-K9,I9))) | P9: =IF(I9=0,0,(MIN(MAX(K9,0),L9)*W9+SUMPRODUCT((Calc!$A$2:$A$1001=A9)*Calc!$G$2:$G$1001*(((K9-(L9+Calc!$J$2:$J$1001))>0)*((K9-(L9+Calc!$J$2:$J$1001))<Calc!$F$2:$F$1001)*(K9-(L9+Calc!$J$2:$J$1001))+((K9-(L9+Calc!$J$2:$J$1001))>=Calc!$F$2:$F$1001)*Calc!$F$2:$F$1001)))) | Q9: =IF(I9=0,0,(MIN(MAX((K9+M9),0),L9)*W9+SUMPRODUCT((Calc!$A$2:$A$1001=A9)*Calc!$G$2:$G$1001*((((K9+M9)-(L9+Calc!$J$2:$J$1001))>0)*(((K9+M9)-(L9+Calc!$J$2:$J$1001))<Calc!$F$2:$F$1001)*((K9+M9)-(L9+Calc!$J$2:$J$1001))+(((K9+M9)-(L9+Calc!$J$2:$J$1001))>=Calc!$F$2:$F$1001)*Calc!$F$2:$F$1001)))) | R9: =IF(I9=0,0,(MIN(MAX((K9+N9),0),L9)*W9+SUMPRODUCT((Calc!$A$2:$A$1001=A9)*Calc!$G$2:$G$1001*((((K9+N9)-(L9+Calc!$J$2:$J$1001))>0)*(((K9+N9)-(L9+Calc!$J$2:$J$1001))<Calc!$F$2:$F$1001)*((K9+N9)-(L9+Calc!$J$2:$J$1001))+(((K9+N9)-(L9+Calc!$J$2:$J$1001))>=Calc!$F$2:$F$1001)*Calc!$F$2:$F$1001)))) | S9: =IF(I9=0,0,(MIN(MAX((K9+O9),0),L9)*W9+SUMPRODUCT((Calc!$A$2:$A$1001=A9)*Calc!$G$2:$G$1001*((((K9+O9)-(L9+Calc!$J$2:$J$1001))>0)*(((K9+O9)-(L9+Calc!$J$2:$J$1001))<Calc!$F$2:$F$1001)*((K9+O9)-(L9+Calc!$J$2:$J$1001))+(((K9+O9)-(L9+Calc!$J$2:$J$1001))>=Calc!$F$2:$F$1001)*Calc!$F$2:$F$1001)))) | T9: =IF(AND(E9=1,B9="RETURN"),Transactions!E9*Transactions!G9,0) | U9: =IF(AND(E9=1,B9="EXPENSE"),Transactions!J9,0) | V9: =IF(AND(Transactions!A9<>"",E9=0),ROW(),"") | W9: =IFERROR(VLOOKUP(A9,Opening!$A:$D,4,0),0)
A10: =IF(Transactions!D10="","",UPPER(TRIM(Transactions!D10))) | B10: =IF(Transactions!C10="","",UPPER(TRIM(Transactions!C10))) | C10: =IF(Transactions!B10="",0,YEAR(Transactions!B10)*100+MONTH(Transactions!B10)) | D10: =IF(Transactions!A10="",1,IF(COUNTIF(Transactions!$A$1:A9,Transactions!A10)>0,1,0)) | E10: =IF(D10=1,0,IF(B10="RETURN",IF(COUNTIFS($A$1:A9,A10,$B$1:B9,"SALE",$E$1:E9,1)>0,1,0),1)) | F10: =IF(E10=1,IF(B10="RECEIPT",Transactions!E10,IF(AND(B10="RETURN",LOWER(TRIM(Transactions!H10))="resellable"),Transactions!E10,0)),0) | G10: =IF(F10>0,IF(B10="RECEIPT",Transactions!F10,IF(_xlfn.MAXIFS($H$2:H10,$A$2:A10,A10)>0,INDEX(Transactions!$F:$F,_xlfn.MAXIFS($H$2:H10,$A$2:A10,A10)),W10)),0) | H10: =IF(AND(E10=1,B10="RECEIPT"),ROW(),0) | I10: =IF(E10=1,IF(OR(B10="SALE",B10="WRITEOFF"),Transactions!E10,0),0) | J10: =SUMIFS($F$1:F9,$A$1:A9,A10) | K10: =SUMIFS($I$1:I9,$A$1:A9,A10) | L10: =IFERROR(VLOOKUP(A10,Opening!$A:$C,3,0),0) | M10: =IF(I10=0,0,MAX(0,MIN(INDEX(Month!H$2:H$13,MATCH($A10,Month!$A$2:$A$13,0))-K10,I10))) | N10: =IF(I10=0,0,MAX(0,MIN(INDEX(Month!I$2:I$13,MATCH($A10,Month!$A$2:$A$13,0))-K10,I10))) | O10: =IF(I10=0,0,MAX(0,MIN(INDEX(Month!J$2:J$13,MATCH($A10,Month!$A$2:$A$13,0))-K10,I10))) | P10: =IF(I10=0,0,(MIN(MAX(K10,0),L10)*W10+SUMPRODUCT((Calc!$A$2:$A$1001=A10)*Calc!$G$2:$G$1001*(((K10-(L10+Calc!$J$2:$J$1001))>0)*((K10-(L10+Calc!$J$2:$J$1001))<Calc!$F$2:$F$1001)*(K10-(L10+Calc!$J$2:$J$1001))+((K10-(L10+Calc!$J$2:$J$1001))>=Calc!$F$2:$F$1001)*Calc!$F$2:$F$1001)))) | Q10: =IF(I10=0,0,(MIN(MAX((K10+M10),0),L10)*W10+SUMPRODUCT((Calc!$A$2:$A$1001=A10)*Calc!$G$2:$G$1001*((((K10+M10)-(L10+Calc!$J$2:$J$1001))>0)*(((K10+M10)-(L10+Calc!$J$2:$J$1001))<Calc!$F$2:$F$1001)*((K10+M10)-(L10+Calc!$J$2:$J$1001))+(((K10+M10)-(L10+Calc!$J$2:$J$1001))>=Calc!$F$2:$F$1001)*Calc!$F$2:$F$1001)))) | R10: =IF(I10=0,0,(MIN(MAX((K10+N10),0),L10)*W10+SUMPRODUCT((Calc!$A$2:$A$1001=A10)*Calc!$G$2:$G$1001*((((K10+N10)-(L10+Calc!$J$2:$J$1001))>0)*(((K10+N10)-(L10+Calc!$J$2:$J$1001))<Calc!$F$2:$F$1001)*((K10+N10)-(L10+Calc!$J$2:$J$1001))+(((K10+N10)-(L10+Calc!$J$2:$J$1001))>=Calc!$F$2:$F$1001)*Calc!$F$2:$F$1001)))) | S10: =IF(I10=0,0,(MIN(MAX((K10+O10),0),L10)*W10+SUMPRODUCT((Calc!$A$2:$A$1001=A10)*Calc!$G$2:$G$1001*((((K10+O10)-(L10+Calc!$J$2:$J$1001))>0)*(((K10+O10)-(L10+Calc!$J$2:$J$1001))<Calc!$F$2:$F$1001)*((K10+O10)-(L10+Calc!$J$2:$J$1001))+(((K10+O10)-(L10+Calc!$J$2:$J$1001))>=Calc!$F$2:$F$1001)*Calc!$F$2:$F$1001)))) | T10: =IF(AND(E10=1,B10="RETURN"),Transactions!E10*Transactions!G10,0) | U10: =IF(AND(E10=1,B10="EXPENSE"),Transactions!J10,0) | V10: =IF(AND(Transactions!A10<>"",E10=0),ROW(),"") | W10: =IFERROR(VLOOKUP(A10,Opening!$A:$D,4,0),0)
A11: =IF(Transactions!D11="","",UPPER(TRIM(Transactions!D11))) | B11: =IF(Transactions!C11="","",UPPER(TRIM(Transactions!C11))) | C11: =IF(Transactions!B11="",0,YEAR(Transactions!B11)*100+MONTH(Transactions!B11)) | D11: =IF(Transactions!A11="",1,IF(COUNTIF(Transactions!$A$1:A10,Transactions!A11)>0,1,0)) | E11: =IF(D11=1,0,IF(B11="RETURN",IF(COUNTIFS($A$1:A10,A11,$B$1:B10,"SALE",$E$1:E10,1)>0,1,0),1)) | F11: =IF(E11=1,IF(B11="RECEIPT",Transactions!E11,IF(AND(B11="RETURN",LOWER(TRIM(Transactions!H11))="resellable"),Transactions!E11,0)),0) | G11: =IF(F11>0,IF(B11="RECEIPT",Transactions!F11,IF(_xlfn.MAXIFS($H$2:H11,$A$2:A11,A11)>0,INDEX(Transactions!$F:$F,_xlfn.MAXIFS($H$2:H11,$A$2:A11,A11)),W11)),0) | H11: =IF(AND(E11=1,B11="RECEIPT"),ROW(),0) | I11: =IF(E11=1,IF(OR(B11="SALE",B11="WRITEOFF"),Transactions!E11,0),0) | J11: =SUMIFS($F$1:F10,$A$1:A10,A11) | K11: =SUMIFS($I$1:I10,$A$1:A10,A11) | L11: =IFERROR(VLOOKUP(A11,Opening!$A:$C,3,0),0) | M11: =IF(I11=0,0,MAX(0,MIN(INDEX(Month!H$2:H$13,MATCH($A11,Month!$A$2:$A$13,0))-K11,I11))) | N11: =IF(I11=0,0,MAX(0,MIN(INDEX(Month!I$2:I$13,MATCH($A11,Month!$A$2:$A$13,0))-K11,I11))) | O11: =IF(I11=0,0,MAX(0,MIN(INDEX(Month!J$2:J$13,MATCH($A11,Month!$A$2:$A$13,0))-K11,I11))) | P11: =IF(I11=0,0,(MIN(MAX(K11,0),L11)*W11+SUMPRODUCT((Calc!$A$2:$A$1001=A11)*Calc!$G$2:$G$1001*(((K11-(L11+Calc!$J$2:$J$1001))>0)*((K11-(L11+Calc!$J$2:$J$1001))<Calc!$F$2:$F$1001)*(K11-(L11+Calc!$J$2:$J$1001))+((K11-(L11+Calc!$J$2:$J$1001))>=Calc!$F$2:$F$1001)*Calc!$F$2:$F$1001)))) | Q11: =IF(I11=0,0,(MIN(MAX((K11+M11),0),L11)*W11+SUMPRODUCT((Calc!$A$2:$A$1001=A11)*Calc!$G$2:$G$1001*((((K11+M11)-(L11+Calc!$J$2:$J$1001))>0)*(((K11+M11)-(L11+Calc!$J$2:$J$1001))<Calc!$F$2:$F$1001)*((K11+M11)-(L11+Calc!$J$2:$J$1001))+(((K11+M11)-(L11+Calc!$J$2:$J$1001))>=Calc!$F$2:$F$1001)*Calc!$F$2:$F$1001)))) | R11: =IF(I11=0,0,(MIN(MAX((K11+N11),0),L11)*W11+SUMPRODUCT((Calc!$A$2:$A$1001=A11)*Calc!$G$2:$G$1001*((((K11+N11)-(L11+Calc!$J$2:$J$1001))>0)*(((K11+N11)-(L11+Calc!$J$2:$J$1001))<Calc!$F$2:$F$1001)*((K11+N11)-(L11+Calc!$J$2:$J$1001))+(((K11+N11)-(L11+Calc!$J$2:$J$1001))>=Calc!$F$2:$F$1001)*Calc!$F$2:$F$1001)))) | S11: =IF(I11=0,0,(MIN(MAX((K11+O11),0),L11)*W11+SUMPRODUCT((Calc!$A$2:$A$1001=A11)*Calc!$G$2:$G$1001*((((K11+O11)-(L11+Calc!$J$2:$J$1001))>0)*(((K11+O11)-(L11+Calc!$J$2:$J$1001))<Calc!$F$2:$F$1001)*((K11+O11)-(L11+Calc!$J$2:$J$1001))+(((K11+O11)-(L11+Calc!$J$2:$J$1001))>=Calc!$F$2:$F$1001)*Calc!$F$2:$F$1001)))) | T11: =IF(AND(E11=1,B11="RETURN"),Transactions!E11*Transactions!G11,0) | U11: =IF(AND(E11=1,B11="EXPENSE"),Transactions!J11,0) | V11: =IF(AND(Transactions!A11<>"",E11=0),ROW(),"") | W11: =IFERROR(VLOOKUP(A11,Opening!$A:$D,4,0),0)
A12: =IF(Transactions!D12="","",UPPER(TRIM(Transactions!D12))) | B12: =IF(Transactions!C12="","",UPPER(TRIM(Transactions!C12))) | C12: =IF(Transactions!B12="",0,YEAR(Transactions!B12)*100+MONTH(Transactions!B12)) | D12: =IF(Transactions!A12="",1,IF(COUNTIF(Transactions!$A$1:A11,Transactions!A12)>0,1,0)) | E12: =IF(D12=1,0,IF(B12="RETURN",IF(COUNTIFS($A$1:A11,A12,$B$1:B11,"SALE",$E$1:E11,1)>0,1,0),1)) | F12: =IF(E12=1,IF(B12="RECEIPT",Transactions!E12,IF(AND(B12="RETURN",LOWER(TRIM(Transactions!H12))="resellable"),Transactions!E12,0)),0) | G12: =IF(F12>0,IF(B12="RECEIPT",Transactions!F12,IF(_xlfn.MAXIFS($H$2:H12,$A$2:A12,A12)>0,INDEX(Transactions!$F:$F,_xlfn.MAXIFS($H$2:H12,$A$2:A12,A12)),W12)),0) | H12: =IF(AND(E12=1,B12="RECEIPT"),ROW(),0) | I12: =IF(E12=1,IF(OR(B12="SALE",B12="WRITEOFF"),Transactions!E12,0),0) | J12: =SUMIFS($F$1:F11,$A$1:A11,A12) | K12: =SUMIFS($I$1:I11,$A$1:A11,A12) | L12: =IFERROR(VLOOKUP(A12,Opening!$A:$C,3,0),0) | M12: =IF(I12=0,0,MAX(0,MIN(INDEX(Month!H$2:H$13,MATCH($A12,Month!$A$2:$A$13,0))-K12,I12))) | N12: =IF(I12=0,0,MAX(0,MIN(INDEX(Month!I$2:I$13,MATCH($A12,Month!$A$2:$A$13,0))-K12,I12))) | O12: =IF(I12=0,0,MAX(0,MIN(INDEX(Month!J$2:J$13,MATCH($A12,Month!$A$2:$A$13,0))-K12,I12))) | P12: =IF(I12=0,0,(MIN(MAX(K12,0),L12)*W12+SUMPRODUCT((Calc!$A$2:$A$1001=A12)*Calc!$G$2:$G$1001*(((K12-(L12+Calc!$J$2:$J$1001))>0)*((K12-(L12+Calc!$J$2:$J$1001))<Calc!$F$2:$F$1001)*(K12-(L12+Calc!$J$2:$J$1001))+((K12-(L12+Calc!$J$2:$J$1001))>=Calc!$F$2:$F$1001)*Calc!$F$2:$F$1001)))) | Q12: =IF(I12=0,0,(MIN(MAX((K12+M12),0),L12)*W12+SUMPRODUCT((Calc!$A$2:$A$1001=A12)*Calc!$G$2:$G$1001*((((K12+M12)-(L12+Calc!$J$2:$J$1001))>0)*(((K12+M12)-(L12+Calc!$J$2:$J$1001))<Calc!$F$2:$F$1001)*((K12+M12)-(L12+Calc!$J$2:$J$1001))+(((K12+M12)-(L12+Calc!$J$2:$J$1001))>=Calc!$F$2:$F$1001)*Calc!$F$2:$F$1001)))) | R12: =IF(I12=0,0,(MIN(MAX((K12+N12),0),L12)*W12+SUMPRODUCT((Calc!$A$2:$A$1001=A12)*Calc!$G$2:$G$1001*((((K12+N12)-(L12+Calc!$J$2:$J$1001))>0)*(((K12+N12)-(L12+Calc!$J$2:$J$1001))<Calc!$F$2:$F$1001)*((K12+N12)-(L12+Calc!$J$2:$J$1001))+(((K12+N12)-(L12+Calc!$J$2:$J$1001))>=Calc!$F$2:$F$1001)*Calc!$F$2:$F$1001)))) | S12: =IF(I12=0,0,(MIN(MAX((K12+O12),0),L12)*W12+SUMPRODUCT((Calc!$A$2:$A$1001=A12)*Calc!$G$2:$G$1001*((((K12+O12)-(L12+Calc!$J$2:$J$1001))>0)*(((K12+O12)-(L12+Calc!$J$2:$J$1001))<Calc!$F$2:$F$1001)*((K12+O12)-(L12+Calc!$J$2:$J$1001))+(((K12+O12)-(L12+Calc!$J$2:$J$1001))>=Calc!$F$2:$F$1001)*Calc!$F$2:$F$1001)))) | T12: =IF(AND(E12=1,B12="RETURN"),Transactions!E12*Transactions!G12,0) | U12: =IF(AND(E12=1,B12="EXPENSE"),Transactions!J12,0) | V12: =IF(AND(Transactions!A12<>"",E12=0),ROW(),"") | W12: =IFERROR(VLOOKUP(A12,Opening!$A:$D,4,0),0)
A13: =IF(Transactions!D13="","",UPPER(TRIM(Transactions!D13))) | B13: =IF(Transactions!C13="","",UPPER(TRIM(Transactions!C13))) | C13: =IF(Transactions!B13="",0,YEAR(Transactions!B13)*100+MONTH(Transactions!B13)) | D13: =IF(Transactions!A13="",1,IF(COUNTIF(Transactions!$A$1:A12,Transactions!A13)>0,1,0)) | E13: =IF(D13=1,0,IF(B13="RETURN",IF(COUNTIFS($A$1:A12,A13,$B$1:B12,"SALE",$E$1:E12,1)>0,1,0),1)) | F13: =IF(E13=1,IF(B13="RECEIPT",Transactions!E13,IF(AND(B13="RETURN",LOWER(TRIM(Transactions!H13))="resellable"),Transactions!E13,0)),0) | G13: =IF(F13>0,IF(B13="RECEIPT",Transactions!F13,IF(_xlfn.MAXIFS($H$2:H13,$A$2:A13,A13)>0,INDEX(Transactions!$F:$F,_xlfn.MAXIFS($H$2:H13,$A$2:A13,A13)),W13)),0) | H13: =IF(AND(E13=1,B13="RECEIPT"),ROW(),0) | I13: =IF(E13=1,IF(OR(B13="SALE",B13="WRITEOFF"),Transactions!E13,0),0) | J13: =SUMIFS($F$1:F12,$A$1:A12,A13) | K13: =SUMIFS($I$1:I12,$A$1:A12,A13) | L13: =IFERROR(VLOOKUP(A13,Opening!$A:$C,3,0),0) | M13: =IF(I13=0,0,MAX(0,MIN(INDEX(Month!H$2:H$13,MATCH($A13,Month!$A$2:$A$13,0))-K13,I13))) | N13: =IF(I13=0,0,MAX(0,MIN(INDEX(Month!I$2:I$13,MATCH($A13,Month!$A$2:$A$13,0))-K13,I13))) | O13: =IF(I13=0,0,MAX(0,MIN(INDEX(Month!J$2:J$13,MATCH($A13,Month!$A$2:$A$13,0))-K13,I13))) | P13: =IF(I13=0,0,(MIN(MAX(K13,0),L13)*W13+SUMPRODUCT((Calc!$A$2:$A$1001=A13)*Calc!$G$2:$G$1001*(((K13-(L13+Calc!$J$2:$J$1001))>0)*((K13-(L13+Calc!$J$2:$J$1001))<Calc!$F$2:$F$1001)*(K13-(L13+Calc!$J$2:$J$1001))+((K13-(L13+Calc!$J$2:$J$1001))>=Calc!$F$2:$F$1001)*Calc!$F$2:$F$1001)))) | Q13: =IF(I13=0,0,(MIN(MAX((K13+M13),0),L13)*W13+SUMPRODUCT((Calc!$A$2:$A$1001=A13)*Calc!$G$2:$G$1001*((((K13+M13)-(L13+Calc!$J$2:$J$1001))>0)*(((K13+M13)-(L13+Calc!$J$2:$J$1001))<Calc!$F$2:$F$1001)*((K13+M13)-(L13+Calc!$J$2:$J$1001))+(((K13+M13)-(L13+Calc!$J$2:$J$1001))>=Calc!$F$2:$F$1001)*Calc!$F$2:$F$1001)))) | R13: =IF(I13=0,0,(MIN(MAX((K13+N13),0),L13)*W13+SUMPRODUCT((Calc!$A$2:$A$1001=A13)*Calc!$G$2:$G$1001*((((K13+N13)-(L13+Calc!$J$2:$J$1001))>0)*(((K13+N13)-(L13+Calc!$J$2:$J$1001))<Calc!$F$2:$F$1001)*((K13+N13)-(L13+Calc!$J$2:$J$1001))+(((K13+N13)-(L13+Calc!$J$2:$J$1001))>=Calc!$F$2:$F$1001)*Calc!$F$2:$F$1001)))) | S13: =IF(I13=0,0,(MIN(MAX((K13+O13),0),L13)*W13+SUMPRODUCT((Calc!$A$2:$A$1001=A13)*Calc!$G$2:$G$1001*((((K13+O13)-(L13+Calc!$J$2:$J$1001))>0)*(((K13+O13)-(L13+Calc!$J$2:$J$1001))<Calc!$F$2:$F$1001)*((K13+O13)-(L13+Calc!$J$2:$J$1001))+(((K13+O13)-(L13+Calc!$J$2:$J$1001))>=Calc!$F$2:$F$1001)*Calc!$F$2:$F$1001)))) | T13: =IF(AND(E13=1,B13="RETURN"),Transactions!E13*Transactions!G13,0) | U13: =IF(AND(E13=1,B13="EXPENSE"),Transactions!J13,0) | V13: =IF(AND(Transactions!A13<>"",E13=0),ROW(),"") | W13: =IFERROR(VLOOKUP(A13,Opening!$A:$D,4,0),0)
... A1001: =IF(Transactions!D1001="","",UPPER(TRIM(Transactions!D1001))) | B1001: =IF(Transactions!C1001="","",UPPER(TRIM(Transactions!C1001))) | C1001: =IF(Transactions!B1001="",0,YEAR(Transactions!B1001)*100+MONTH(Transactions!B1001)) | D1001: =IF(Transactions!A1001="",1,IF(COUNTIF(Transactions!$A$1:A1000,Transactions!A1001)>0,1,0)) | E1001: =IF(D1001=1,0,IF(B1001="RETURN",IF(COUNTIFS($A$1:A1000,A1001,$B$1:B1000,"SALE",$E$1:E1000,1)>0,1,0),1)) | F1001: =IF(E1001=1,IF(B1001="RECEIPT",Transactions!E1001,IF(AND(B1001="RETURN",LOWER(TRIM(Transactions!H1001))="resellable"),Transactions!E1001,0)),0) | G1001: =IF(F1001>0,IF(B1001="RECEIPT",Transactions!F1001,IF(_xlfn.MAXIFS($H$2:H1001,$A$2:A1001,A1001)>0,INDEX(Transactions!$F:$F,_xlfn.MAXIFS($H$2:H1001,$A$2:A1001,A1001)),W1001)),0) | H1001: =IF(AND(E1001=1,B1001="RECEIPT"),ROW(),0) | I1001: =IF(E1001=1,IF(OR(B1001="SALE",B1001="WRITEOFF"),Transactions!E1001,0),0) | J1001: =SUMIFS($F$1:F1000,$A$1:A1000,A1001) | K1001: =SUMIFS($I$1:I1000,$A$1:A1000,A1001) | L1001: =IFERROR(VLOOKUP(A1001,Opening!$A:$C,3,0),0) | M1001: =IF(I1001=0,0,MAX(0,MIN(INDEX(Month!H$2:H$13,MATCH($A1001,Month!$A$2:$A$13,0))-K1001,I1001))) | N1001: =IF(I1001=0,0,MAX(0,MIN(INDEX(Month!I$2:I$13,MATCH($A1001,Month!$A$2:$A$13,0))-K1001,I1001))) | O1001: =IF(I1001=0,0,MAX(0,MIN(INDEX(Month!J$2:J$13,MATCH($A1001,Month!$A$2:$A$13,0))-K1001,I1001))) | P1001: =IF(I1001=0,0,(MIN(MAX(K1001,0),L1001)*W1001+SUMPRODUCT((Calc!$A$2:$A$1001=A1001)*Calc!$G$2:$G$1001*(((K1001-(L1001+Calc!$J$2:$J$1001))>0)*((K1001-(L1001+Calc!$J$2:$J$1001))<Calc!$F$2:$F$1001)*(K1001-(L1001+Calc!$J$2:$J$1001))+((K1001-(L1001+Calc!$J$2:$J$1001))>=Calc!$F$2:$F$1001)*Calc!$F$2:$F$1001)))) | Q1001: =IF(I1001=0,0,(MIN(MAX((K1001+M1001),0),L1001)*W1001+SUMPRODUCT((Calc!$A$2:$A$1001=A1001)*Calc!$G$2:$G$1001*((((K1001+M1001)-(L1001+Calc!$J$2:$J$1001))>0)*(((K1001+M1001)-(L1001+Calc!$J$2:$J$1001))<Calc!$F$2:$F$1001)*((K1001+M1001)-(L1001+Calc!$J$2:$J$1001))+(((K1001+M1001)-(L1001+Calc!$J$2:$J$1001))>=Calc!$F$2:$F$1001)*Calc!$F$2:$F$1001)))) | R1001: =IF(I1001=0,0,(MIN(MAX((K1001+N1001),0),L1001)*W1001+SUMPRODUCT((Calc!$A$2:$A$1001=A1001)*Calc!$G$2:$G$1001*((((K1001+N1001)-(L1001+Calc!$J$2:$J$1001))>0)*(((K1001+N1001)-(L1001+Calc!$J$2:$J$1001))<Calc!$F$2:$F$1001)*((K1001+N1001)-(L1001+Calc!$J$2:$J$1001))+(((K1001+N1001)-(L1001+Calc!$J$2:$J$1001))>=Calc!$F$2:$F$1001)*Calc!$F$2:$F$1001)))) | S1001: =IF(I1001=0,0,(MIN(MAX((K1001+O1001),0),L1001)*W1001+SUMPRODUCT((Calc!$A$2:$A$1001=A1001)*Calc!$G$2:$G$1001*((((K1001+O1001)-(L1001+Calc!$J$2:$J$1001))>0)*(((K1001+O1001)-(L1001+Calc!$J$2:$J$1001))<Calc!$F$2:$F$1001)*((K1001+O1001)-(L1001+Calc!$J$2:$J$1001))+(((K1001+O1001)-(L1001+Calc!$J$2:$J$1001))>=Calc!$F$2:$F$1001)*Calc!$F$2:$F$1001)))) | T1001: =IF(AND(E1001=1,B1001="RETURN"),Transactions!E1001*Transactions!G1001,0) | U1001: =IF(AND(E1001=1,B1001="EXPENSE"),Transactions!J1001,0) | V1001: =IF(AND(Transactions!A1001<>"",E1001=0),ROW(),"") | W1001: =IFERROR(VLOOKUP(A1001,Opening!$A:$D,4,0),0)

Sheet Month
A1: SKU | B1: Demand≤Jul | C1: Demand≤Aug | D1: Demand≤Sep | E1: Supply≤Jul | F1: Supply≤Aug | G1: Supply≤Sep | H1: Shipped≤Jul | I1: Shipped≤Aug | J1: Shipped≤Sep
A2: =Opening!A2 | B2: =SUMIFS(Calc!$I$2:$I$1001,Calc!$A$2:$A$1001,$A2,Calc!$C$2:$C$1001,"<="&202507) | C2: =SUMIFS(Calc!$I$2:$I$1001,Calc!$A$2:$A$1001,$A2,Calc!$C$2:$C$1001,"<="&202508) | D2: =SUMIFS(Calc!$I$2:$I$1001,Calc!$A$2:$A$1001,$A2,Calc!$C$2:$C$1001,"<="&202509) | E2: =Opening!C2+SUMIFS(Calc!$F$2:$F$1001,Calc!$A$2:$A$1001,$A2,Calc!$C$2:$C$1001,"<="&202507) | F2: =Opening!C2+SUMIFS(Calc!$F$2:$F$1001,Calc!$A$2:$A$1001,$A2,Calc!$C$2:$C$1001,"<="&202508) | G2: =Opening!C2+SUMIFS(Calc!$F$2:$F$1001,Calc!$A$2:$A$1001,$A2,Calc!$C$2:$C$1001,"<="&202509) | H2: =MIN(B2,E2) | I2: =MIN(C2,F2) | J2: =MIN(D2,G2)
A3: =Opening!A3 | B3: =SUMIFS(Calc!$I$2:$I$1001,Calc!$A$2:$A$1001,$A3,Calc!$C$2:$C$1001,"<="&202507) | C3: =SUMIFS(Calc!$I$2:$I$1001,Calc!$A$2:$A$1001,$A3,Calc!$C$2:$C$1001,"<="&202508) | D3: =SUMIFS(Calc!$I$2:$I$1001,Calc!$A$2:$A$1001,$A3,Calc!$C$2:$C$1001,"<="&202509) | E3: =Opening!C3+SUMIFS(Calc!$F$2:$F$1001,Calc!$A$2:$A$1001,$A3,Calc!$C$2:$C$1001,"<="&202507) | F3: =Opening!C3+SUMIFS(Calc!$F$2:$F$1001,Calc!$A$2:$A$1001,$A3,Calc!$C$2:$C$1001,"<="&202508) | G3: =Opening!C3+SUMIFS(Calc!$F$2:$F$1001,Calc!$A$2:$A$1001,$A3,Calc!$C$2:$C$1001,"<="&202509) | H3: =MIN(B3,E3) | I3: =MIN(C3,F3) | J3: =MIN(D3,G3)
A4: =Opening!A4 | B4: =SUMIFS(Calc!$I$2:$I$1001,Calc!$A$2:$A$1001,$A4,Calc!$C$2:$C$1001,"<="&202507) | C4: =SUMIFS(Calc!$I$2:$I$1001,Calc!$A$2:$A$1001,$A4,Calc!$C$2:$C$1001,"<="&202508) | D4: =SUMIFS(Calc!$I$2:$I$1001,Calc!$A$2:$A$1001,$A4,Calc!$C$2:$C$1001,"<="&202509) | E4: =Opening!C4+SUMIFS(Calc!$F$2:$F$1001,Calc!$A$2:$A$1001,$A4,Calc!$C$2:$C$1001,"<="&202507) | F4: =Opening!C4+SUMIFS(Calc!$F$2:$F$1001,Calc!$A$2:$A$1001,$A4,Calc!$C$2:$C$1001,"<="&202508) | G4: =Opening!C4+SUMIFS(Calc!$F$2:$F$1001,Calc!$A$2:$A$1001,$A4,Calc!$C$2:$C$1001,"<="&202509) | H4: =MIN(B4,E4) | I4: =MIN(C4,F4) | J4: =MIN(D4,G4)
A5: =Opening!A5 | B5: =SUMIFS(Calc!$I$2:$I$1001,Calc!$A$2:$A$1001,$A5,Calc!$C$2:$C$1001,"<="&202507) | C5: =SUMIFS(Calc!$I$2:$I$1001,Calc!$A$2:$A$1001,$A5,Calc!$C$2:$C$1001,"<="&202508) | D5: =SUMIFS(Calc!$I$2:$I$1001,Calc!$A$2:$A$1001,$A5,Calc!$C$2:$C$1001,"<="&202509) | E5: =Opening!C5+SUMIFS(Calc!$F$2:$F$1001,Calc!$A$2:$A$1001,$A5,Calc!$C$2:$C$1001,"<="&202507) | F5: =Opening!C5+SUMIFS(Calc!$F$2:$F$1001,Calc!$A$2:$A$1001,$A5,Calc!$C$2:$C$1001,"<="&202508) | G5: =Opening!C5+SUMIFS(Calc!$F$2:$F$1001,Calc!$A$2:$A$1001,$A5,Calc!$C$2:$C$1001,"<="&202509) | H5: =MIN(B5,E5) | I5: =MIN(C5,F5) | J5: =MIN(D5,G5)
A6: =Opening!A6 | B6: =SUMIFS(Calc!$I$2:$I$1001,Calc!$A$2:$A$1001,$A6,Calc!$C$2:$C$1001,"<="&202507) | C6: =SUMIFS(Calc!$I$2:$I$1001,Calc!$A$2:$A$1001,$A6,Calc!$C$2:$C$1001,"<="&202508) | D6: =SUMIFS(Calc!$I$2:$I$1001,Calc!$A$2:$A$1001,$A6,Calc!$C$2:$C$1001,"<="&202509) | E6: =Opening!C6+SUMIFS(Calc!$F$2:$F$1001,Calc!$A$2:$A$1001,$A6,Calc!$C$2:$C$1001,"<="&202507) | F6: =Opening!C6+SUMIFS(Calc!$F$2:$F$1001,Calc!$A$2:$A$1001,$A6,Calc!$C$2:$C$1001,"<="&202508) | G6: =Opening!C6+SUMIFS(Calc!$F$2:$F$1001,Calc!$A$2:$A$1001,$A6,Calc!$C$2:$C$1001,"<="&202509) | H6: =MIN(B6,E6) | I6: =MIN(C6,F6) | J6: =MIN(D6,G6)
A7: =Opening!A7 | B7: =SUMIFS(Calc!$I$2:$I$1001,Calc!$A$2:$A$1001,$A7,Calc!$C$2:$C$1001,"<="&202507) | C7: =SUMIFS(Calc!$I$2:$I$1001,Calc!$A$2:$A$1001,$A7,Calc!$C$2:$C$1001,"<="&202508) | D7: =SUMIFS(Calc!$I$2:$I$1001,Calc!$A$2:$A$1001,$A7,Calc!$C$2:$C$1001,"<="&202509) | E7: =Opening!C7+SUMIFS(Calc!$F$2:$F$1001,Calc!$A$2:$A$1001,$A7,Calc!$C$2:$C$1001,"<="&202507) | F7: =Opening!C7+SUMIFS(Calc!$F$2:$F$1001,Calc!$A$2:$A$1001,$A7,Calc!$C$2:$C$1001,"<="&202508) | G7: =Opening!C7+SUMIFS(Calc!$F$2:$F$1001,Calc!$A$2:$A$1001,$A7,Calc!$C$2:$C$1001,"<="&202509) | H7: =MIN(B7,E7) | I7: =MIN(C7,F7) | J7: =MIN(D7,G7)
A8: =Opening!A8 | B8: =SUMIFS(Calc!$I$2:$I$1001,Calc!$A$2:$A$1001,$A8,Calc!$C$2:$C$1001,"<="&202507) | C8: =SUMIFS(Calc!$I$2:$I$1001,Calc!$A$2:$A$1001,$A8,Calc!$C$2:$C$1001,"<="&202508) | D8: =SUMIFS(Calc!$I$2:$I$1001,Calc!$A$2:$A$1001,$A8,Calc!$C$2:$C$1001,"<="&202509) | E8: =Opening!C8+SUMIFS(Calc!$F$2:$F$1001,Calc!$A$2:$A$1001,$A8,Calc!$C$2:$C$1001,"<="&202507) | F8: =Opening!C8+SUMIFS(Calc!$F$2:$F$1001,Calc!$A$2:$A$1001,$A8,Calc!$C$2:$C$1001,"<="&202508) | G8: =Opening!C8+SUMIFS(Calc!$F$2:$F$1001,Calc!$A$2:$A$1001,$A8,Calc!$C$2:$C$1001,"<="&202509) | H8: =MIN(B8,E8) | I8: =MIN(C8,F8) | J8: =MIN(D8,G8)
A9: =Opening!A9 | B9: =SUMIFS(Calc!$I$2:$I$1001,Calc!$A$2:$A$1001,$A9,Calc!$C$2:$C$1001,"<="&202507) | C9: =SUMIFS(Calc!$I$2:$I$1001,Calc!$A$2:$A$1001,$A9,Calc!$C$2:$C$1001,"<="&202508) | D9: =SUMIFS(Calc!$I$2:$I$1001,Calc!$A$2:$A$1001,$A9,Calc!$C$2:$C$1001,"<="&202509) | E9: =Opening!C9+SUMIFS(Calc!$F$2:$F$1001,Calc!$A$2:$A$1001,$A9,Calc!$C$2:$C$1001,"<="&202507) | F9: =Opening!C9+SUMIFS(Calc!$F$2:$F$1001,Calc!$A$2:$A$1001,$A9,Calc!$C$2:$C$1001,"<="&202508) | G9: =Opening!C9+SUMIFS(Calc!$F$2:$F$1001,Calc!$A$2:$A$1001,$A9,Calc!$C$2:$C$1001,"<="&202509) | H9: =MIN(B9,E9) | I9: =MIN(C9,F9) | J9: =MIN(D9,G9)
A10: =Opening!A10 | B10: =SUMIFS(Calc!$I$2:$I$1001,Calc!$A$2:$A$1001,$A10,Calc!$C$2:$C$1001,"<="&202507) | C10: =SUMIFS(Calc!$I$2:$I$1001,Calc!$A$2:$A$1001,$A10,Calc!$C$2:$C$1001,"<="&202508) | D10: =SUMIFS(Calc!$I$2:$I$1001,Calc!$A$2:$A$1001,$A10,Calc!$C$2:$C$1001,"<="&202509) | E10: =Opening!C10+SUMIFS(Calc!$F$2:$F$1001,Calc!$A$2:$A$1001,$A10,Calc!$C$2:$C$1001,"<="&202507) | F10: =Opening!C10+SUMIFS(Calc!$F$2:$F$1001,Calc!$A$2:$A$1001,$A10,Calc!$C$2:$C$1001,"<="&202508) | G10: =Opening!C10+SUMIFS(Calc!$F$2:$F$1001,Calc!$A$2:$A$1001,$A10,Calc!$C$2:$C$1001,"<="&202509) | H10: =MIN(B10,E10) | I10: =MIN(C10,F10) | J10: =MIN(D10,G10)
A11: =Opening!A11 | B11: =SUMIFS(Calc!$I$2:$I$1001,Calc!$A$2:$A$1001,$A11,Calc!$C$2:$C$1001,"<="&202507) | C11: =SUMIFS(Calc!$I$2:$I$1001,Calc!$A$2:$A$1001,$A11,Calc!$C$2:$C$1001,"<="&202508) | D11: =SUMIFS(Calc!$I$2:$I$1001,Calc!$A$2:$A$1001,$A11,Calc!$C$2:$C$1001,"<="&202509) | E11: =Opening!C11+SUMIFS(Calc!$F$2:$F$1001,Calc!$A$2:$A$1001,$A11,Calc!$C$2:$C$1001,"<="&202507) | F11: =Opening!C11+SUMIFS(Calc!$F$2:$F$1001,Calc!$A$2:$A$1001,$A11,Calc!$C$2:$C$1001,"<="&202508) | G11: =Opening!C11+SUMIFS(Calc!$F$2:$F$1001,Calc!$A$2:$A$1001,$A11,Calc!$C$2:$C$1001,"<="&202509) | H11: =MIN(B11,E11) | I11: =MIN(C11,F11) | J11: =MIN(D11,G11)
A12: =Opening!A12 | B12: =SUMIFS(Calc!$I$2:$I$1001,Calc!$A$2:$A$1001,$A12,Calc!$C$2:$C$1001,"<="&202507) | C12: =SUMIFS(Calc!$I$2:$I$1001,Calc!$A$2:$A$1001,$A12,Calc!$C$2:$C$1001,"<="&202508) | D12: =SUMIFS(Calc!$I$2:$I$1001,Calc!$A$2:$A$1001,$A12,Calc!$C$2:$C$1001,"<="&202509) | E12: =Opening!C12+SUMIFS(Calc!$F$2:$F$1001,Calc!$A$2:$A$1001,$A12,Calc!$C$2:$C$1001,"<="&202507) | F12: =Opening!C12+SUMIFS(Calc!$F$2:$F$1001,Calc!$A$2:$A$1001,$A12,Calc!$C$2:$C$1001,"<="&202508) | G12: =Opening!C12+SUMIFS(Calc!$F$2:$F$1001,Calc!$A$2:$A$1001,$A12,Calc!$C$2:$C$1001,"<="&202509) | H12: =MIN(B12,E12) | I12: =MIN(C12,F12) | J12: =MIN(D12,G12)
A13: =Opening!A13 | B13: =SUMIFS(Calc!$I$2:$I$1001,Calc!$A$2:$A$1001,$A13,Calc!$C$2:$C$1001,"<="&202507) | C13: =SUMIFS(Calc!$I$2:$I$1001,Calc!$A$2:$A$1001,$A13,Calc!$C$2:$C$1001,"<="&202508) | D13: =SUMIFS(Calc!$I$2:$I$1001,Calc!$A$2:$A$1001,$A13,Calc!$C$2:$C$1001,"<="&202509) | E13: =Opening!C13+SUMIFS(Calc!$F$2:$F$1001,Calc!$A$2:$A$1001,$A13,Calc!$C$2:$C$1001,"<="&202507) | F13: =Opening!C13+SUMIFS(Calc!$F$2:$F$1001,Calc!$A$2:$A$1001,$A13,Calc!$C$2:$C$1001,"<="&202508) | G13: =Opening!C13+SUMIFS(Calc!$F$2:$F$1001,Calc!$A$2:$A$1001,$A13,Calc!$C$2:$C$1001,"<="&202509) | H13: =MIN(B13,E13) | I13: =MIN(C13,F13) | J13: =MIN(D13,G13)

Sheet Summary
A1: Pip's Outdoor Gear — Q3 2025 P&L
A2: Metric | B2: 2025-07 | C2: 2025-08 | D2: 2025-09 | E2: Q3 total
A3: Revenue | B3: =SUMPRODUCT((Calc!$B$2:$B$1001="SALE")*Transactions!$G$2:$G$1001*(Calc!$M$2:$M$1001-0)) | C3: =SUMPRODUCT((Calc!$B$2:$B$1001="SALE")*Transactions!$G$2:$G$1001*(Calc!$N$2:$N$1001-Calc!$M$2:$M$1001)) | D3: =SUMPRODUCT((Calc!$B$2:$B$1001="SALE")*Transactions!$G$2:$G$1001*(Calc!$O$2:$O$1001-Calc!$N$2:$N$1001)) | E3: =SUM(B3:D3)
A4: Refunds | B4: =SUMIFS(Calc!$T$2:$T$1001,Calc!$C$2:$C$1001,202507) | C4: =SUMIFS(Calc!$T$2:$T$1001,Calc!$C$2:$C$1001,202508) | D4: =SUMIFS(Calc!$T$2:$T$1001,Calc!$C$2:$C$1001,202509) | E4: =SUM(B4:D4)
A5: COGS | B5: =SUMPRODUCT((Calc!$B$2:$B$1001="SALE")*(Calc!$Q$2:$Q$1001-Calc!$P$2:$P$1001)) | C5: =SUMPRODUCT((Calc!$B$2:$B$1001="SALE")*(Calc!$R$2:$R$1001-Calc!$Q$2:$Q$1001)) | D5: =SUMPRODUCT((Calc!$B$2:$B$1001="SALE")*(Calc!$S$2:$S$1001-Calc!$R$2:$R$1001)) | E5: =SUM(B5:D5)
A6: Write-offs | B6: =SUMPRODUCT((Calc!$B$2:$B$1001="WRITEOFF")*(Calc!$Q$2:$Q$1001-Calc!$P$2:$P$1001)) | C6: =SUMPRODUCT((Calc!$B$2:$B$1001="WRITEOFF")*(Calc!$R$2:$R$1001-Calc!$Q$2:$Q$1001)) | D6: =SUMPRODUCT((Calc!$B$2:$B$1001="WRITEOFF")*(Calc!$S$2:$S$1001-Calc!$R$2:$R$1001)) | E6: =SUM(B6:D6)
A7: Gross profit | B7: =B3-B4-B5-B6 | C7: =C3-C4-C5-C6 | D7: =D3-D4-D5-D6 | E7: =SUM(B7:D7)
A8: Operating expenses | B8: =SUMIFS(Calc!$U$2:$U$1001,Calc!$C$2:$C$1001,202507) | C8: =SUMIFS(Calc!$U$2:$U$1001,Calc!$C$2:$C$1001,202508) | D8: =SUMIFS(Calc!$U$2:$U$1001,Calc!$C$2:$C$1001,202509) | E8: =SUM(B8:D8)
A9: Net profit | B9: =B7-B8 | C9: =C7-C8 | D9: =D7-D8 | E9: =SUM(B9:D9)

Sheet Stock
A1: SKU | B1: On hand | C1: Backordered | D1: Stock value (FIFO) | E1: Reorder? | F1: Reorder qty
A2: =Opening!A2 | B2: =Month!G2-Month!J2 | C2: =SUMPRODUCT((Calc!$A$2:$A$1001=$A2)*(Calc!$B$2:$B$1001="SALE")*(Calc!$I$2:$I$1001-Calc!$O$2:$O$1001)) | D2: =ROUND((MIN(MAX(Month!G2,0),Opening!C2)*Opening!D2+SUMPRODUCT((Calc!$A$2:$A$1001=$A2)*Calc!$G$2:$G$1001*(((Month!G2-(Opening!C2+Calc!$J$2:$J$1001))>0)*((Month!G2-(Opening!C2+Calc!$J$2:$J$1001))<Calc!$F$2:$F$1001)*(Month!G2-(Opening!C2+Calc!$J$2:$J$1001))+((Month!G2-(Opening!C2+Calc!$J$2:$J$1001))>=Calc!$F$2:$F$1001)*Calc!$F$2:$F$1001)))-(MIN(MAX(Month!J2,0),Opening!C2)*Opening!D2+SUMPRODUCT((Calc!$A$2:$A$1001=$A2)*Calc!$G$2:$G$1001*(((Month!J2-(Opening!C2+Calc!$J$2:$J$1001))>0)*((Month!J2-(Opening!C2+Calc!$J$2:$J$1001))<Calc!$F$2:$F$1001)*(Month!J2-(Opening!C2+Calc!$J$2:$J$1001))+((Month!J2-(Opening!C2+Calc!$J$2:$J$1001))>=Calc!$F$2:$F$1001)*Calc!$F$2:$F$1001))),2) | E2: =IF(B2<Opening!F2,"YES","NO") | F2: =IF(E2="YES",Opening!G2,0)
A3: =Opening!A3 | B3: =Month!G3-Month!J3 | C3: =SUMPRODUCT((Calc!$A$2:$A$1001=$A3)*(Calc!$B$2:$B$1001="SALE")*(Calc!$I$2:$I$1001-Calc!$O$2:$O$1001)) | D3: =ROUND((MIN(MAX(Month!G3,0),Opening!C3)*Opening!D3+SUMPRODUCT((Calc!$A$2:$A$1001=$A3)*Calc!$G$2:$G$1001*(((Month!G3-(Opening!C3+Calc!$J$2:$J$1001))>0)*((Month!G3-(Opening!C3+Calc!$J$2:$J$1001))<Calc!$F$2:$F$1001)*(Month!G3-(Opening!C3+Calc!$J$2:$J$1001))+((Month!G3-(Opening!C3+Calc!$J$2:$J$1001))>=Calc!$F$2:$F$1001)*Calc!$F$2:$F$1001)))-(MIN(MAX(Month!J3,0),Opening!C3)*Opening!D3+SUMPRODUCT((Calc!$A$2:$A$1001=$A3)*Calc!$G$2:$G$1001*(((Month!J3-(Opening!C3+Calc!$J$2:$J$1001))>0)*((Month!J3-(Opening!C3+Calc!$J$2:$J$1001))<Calc!$F$2:$F$1001)*(Month!J3-(Opening!C3+Calc!$J$2:$J$1001))+((Month!J3-(Opening!C3+Calc!$J$2:$J$1001))>=Calc!$F$2:$F$1001)*Calc!$F$2:$F$1001))),2) | E3: =IF(B3<Opening!F3,"YES","NO") | F3: =IF(E3="YES",Opening!G3,0)
A4: =Opening!A4 | B4: =Month!G4-Month!J4 | C4: =SUMPRODUCT((Calc!$A$2:$A$1001=$A4)*(Calc!$B$2:$B$1001="SALE")*(Calc!$I$2:$I$1001-Calc!$O$2:$O$1001)) | D4: =ROUND((MIN(MAX(Month!G4,0),Opening!C4)*Opening!D4+SUMPRODUCT((Calc!$A$2:$A$1001=$A4)*Calc!$G$2:$G$1001*(((Month!G4-(Opening!C4+Calc!$J$2:$J$1001))>0)*((Month!G4-(Opening!C4+Calc!$J$2:$J$1001))<Calc!$F$2:$F$1001)*(Month!G4-(Opening!C4+Calc!$J$2:$J$1001))+((Month!G4-(Opening!C4+Calc!$J$2:$J$1001))>=Calc!$F$2:$F$1001)*Calc!$F$2:$F$1001)))-(MIN(MAX(Month!J4,0),Opening!C4)*Opening!D4+SUMPRODUCT((Calc!$A$2:$A$1001=$A4)*Calc!$G$2:$G$1001*(((Month!J4-(Opening!C4+Calc!$J$2:$J$1001))>0)*((Month!J4-(Opening!C4+Calc!$J$2:$J$1001))<Calc!$F$2:$F$1001)*(Month!J4-(Opening!C4+Calc!$J$2:$J$1001))+((Month!J4-(Opening!C4+Calc!$J$2:$J$1001))>=Calc!$F$2:$F$1001)*Calc!$F$2:$F$1001))),2) | E4: =IF(B4<Opening!F4,"YES","NO") | F4: =IF(E4="YES",Opening!G4,0)
A5: =Opening!A5 | B5: =Month!G5-Month!J5 | C5: =SUMPRODUCT((Calc!$A$2:$A$1001=$A5)*(Calc!$B$2:$B$1001="SALE")*(Calc!$I$2:$I$1001-Calc!$O$2:$O$1001)) | D5: =ROUND((MIN(MAX(Month!G5,0),Opening!C5)*Opening!D5+SUMPRODUCT((Calc!$A$2:$A$1001=$A5)*Calc!$G$2:$G$1001*(((Month!G5-(Opening!C5+Calc!$J$2:$J$1001))>0)*((Month!G5-(Opening!C5+Calc!$J$2:$J$1001))<Calc!$F$2:$F$1001)*(Month!G5-(Opening!C5+Calc!$J$2:$J$1001))+((Month!G5-(Opening!C5+Calc!$J$2:$J$1001))>=Calc!$F$2:$F$1001)*Calc!$F$2:$F$1001)))-(MIN(MAX(Month!J5,0),Opening!C5)*Opening!D5+SUMPRODUCT((Calc!$A$2:$A$1001=$A5)*Calc!$G$2:$G$1001*(((Month!J5-(Opening!C5+Calc!$J$2:$J$1001))>0)*((Month!J5-(Opening!C5+Calc!$J$2:$J$1001))<Calc!$F$2:$F$1001)*(Month!J5-(Opening!C5+Calc!$J$2:$J$1001))+((Month!J5-(Opening!C5+Calc!$J$2:$J$1001))>=Calc!$F$2:$F$1001)*Calc!$F$2:$F$1001))),2) | E5: =IF(B5<Opening!F5,"YES","NO") | F5: =IF(E5="YES",Opening!G5,0)
A6: =Opening!A6 | B6: =Month!G6-Month!J6 | C6: =SUMPRODUCT((Calc!$A$2:$A$1001=$A6)*(Calc!$B$2:$B$1001="SALE")*(Calc!$I$2:$I$1001-Calc!$O$2:$O$1001)) | D6: =ROUND((MIN(MAX(Month!G6,0),Opening!C6)*Opening!D6+SUMPRODUCT((Calc!$A$2:$A$1001=$A6)*Calc!$G$2:$G$1001*(((Month!G6-(Opening!C6+Calc!$J$2:$J$1001))>0)*((Month!G6-(Opening!C6+Calc!$J$2:$J$1001))<Calc!$F$2:$F$1001)*(Month!G6-(Opening!C6+Calc!$J$2:$J$1001))+((Month!G6-(Opening!C6+Calc!$J$2:$J$1001))>=Calc!$F$2:$F$1001)*Calc!$F$2:$F$1001)))-(MIN(MAX(Month!J6,0),Opening!C6)*Opening!D6+SUMPRODUCT((Calc!$A$2:$A$1001=$A6)*Calc!$G$2:$G$1001*(((Month!J6-(Opening!C6+Calc!$J$2:$J$1001))>0)*((Month!J6-(Opening!C6+Calc!$J$2:$J$1001))<Calc!$F$2:$F$1001)*(Month!J6-(Opening!C6+Calc!$J$2:$J$1001))+((Month!J6-(Opening!C6+Calc!$J$2:$J$1001))>=Calc!$F$2:$F$1001)*Calc!$F$2:$F$1001))),2) | E6: =IF(B6<Opening!F6,"YES","NO") | F6: =IF(E6="YES",Opening!G6,0)
A7: =Opening!A7 | B7: =Month!G7-Month!J7 | C7: =SUMPRODUCT((Calc!$A$2:$A$1001=$A7)*(Calc!$B$2:$B$1001="SALE")*(Calc!$I$2:$I$1001-Calc!$O$2:$O$1001)) | D7: =ROUND((MIN(MAX(Month!G7,0),Opening!C7)*Opening!D7+SUMPRODUCT((Calc!$A$2:$A$1001=$A7)*Calc!$G$2:$G$1001*(((Month!G7-(Opening!C7+Calc!$J$2:$J$1001))>0)*((Month!G7-(Opening!C7+Calc!$J$2:$J$1001))<Calc!$F$2:$F$1001)*(Month!G7-(Opening!C7+Calc!$J$2:$J$1001))+((Month!G7-(Opening!C7+Calc!$J$2:$J$1001))>=Calc!$F$2:$F$1001)*Calc!$F$2:$F$1001)))-(MIN(MAX(Month!J7,0),Opening!C7)*Opening!D7+SUMPRODUCT((Calc!$A$2:$A$1001=$A7)*Calc!$G$2:$G$1001*(((Month!J7-(Opening!C7+Calc!$J$2:$J$1001))>0)*((Month!J7-(Opening!C7+Calc!$J$2:$J$1001))<Calc!$F$2:$F$1001)*(Month!J7-(Opening!C7+Calc!$J$2:$J$1001))+((Month!J7-(Opening!C7+Calc!$J$2:$J$1001))>=Calc!$F$2:$F$1001)*Calc!$F$2:$F$1001))),2) | E7: =IF(B7<Opening!F7,"YES","NO") | F7: =IF(E7="YES",Opening!G7,0)
A8: =Opening!A8 | B8: =Month!G8-Month!J8 | C8: =SUMPRODUCT((Calc!$A$2:$A$1001=$A8)*(Calc!$B$2:$B$1001="SALE")*(Calc!$I$2:$I$1001-Calc!$O$2:$O$1001)) | D8: =ROUND((MIN(MAX(Month!G8,0),Opening!C8)*Opening!D8+SUMPRODUCT((Calc!$A$2:$A$1001=$A8)*Calc!$G$2:$G$1001*(((Month!G8-(Opening!C8+Calc!$J$2:$J$1001))>0)*((Month!G8-(Opening!C8+Calc!$J$2:$J$1001))<Calc!$F$2:$F$1001)*(Month!G8-(Opening!C8+Calc!$J$2:$J$1001))+((Month!G8-(Opening!C8+Calc!$J$2:$J$1001))>=Calc!$F$2:$F$1001)*Calc!$F$2:$F$1001)))-(MIN(MAX(Month!J8,0),Opening!C8)*Opening!D8+SUMPRODUCT((Calc!$A$2:$A$1001=$A8)*Calc!$G$2:$G$1001*(((Month!J8-(Opening!C8+Calc!$J$2:$J$1001))>0)*((Month!J8-(Opening!C8+Calc!$J$2:$J$1001))<Calc!$F$2:$F$1001)*(Month!J8-(Opening!C8+Calc!$J$2:$J$1001))+((Month!J8-(Opening!C8+Calc!$J$2:$J$1001))>=Calc!$F$2:$F$1001)*Calc!$F$2:$F$1001))),2) | E8: =IF(B8<Opening!F8,"YES","NO") | F8: =IF(E8="YES",Opening!G8,0)
A9: =Opening!A9 | B9: =Month!G9-Month!J9 | C9: =SUMPRODUCT((Calc!$A$2:$A$1001=$A9)*(Calc!$B$2:$B$1001="SALE")*(Calc!$I$2:$I$1001-Calc!$O$2:$O$1001)) | D9: =ROUND((MIN(MAX(Month!G9,0),Opening!C9)*Opening!D9+SUMPRODUCT((Calc!$A$2:$A$1001=$A9)*Calc!$G$2:$G$1001*(((Month!G9-(Opening!C9+Calc!$J$2:$J$1001))>0)*((Month!G9-(Opening!C9+Calc!$J$2:$J$1001))<Calc!$F$2:$F$1001)*(Month!G9-(Opening!C9+Calc!$J$2:$J$1001))+((Month!G9-(Opening!C9+Calc!$J$2:$J$1001))>=Calc!$F$2:$F$1001)*Calc!$F$2:$F$1001)))-(MIN(MAX(Month!J9,0),Opening!C9)*Opening!D9+SUMPRODUCT((Calc!$A$2:$A$1001=$A9)*Calc!$G$2:$G$1001*(((Month!J9-(Opening!C9+Calc!$J$2:$J$1001))>0)*((Month!J9-(Opening!C9+Calc!$J$2:$J$1001))<Calc!$F$2:$F$1001)*(Month!J9-(Opening!C9+Calc!$J$2:$J$1001))+((Month!J9-(Opening!C9+Calc!$J$2:$J$1001))>=Calc!$F$2:$F$1001)*Calc!$F$2:$F$1001))),2) | E9: =IF(B9<Opening!F9,"YES","NO") | F9: =IF(E9="YES",Opening!G9,0)
A10: =Opening!A10 | B10: =Month!G10-Month!J10 | C10: =SUMPRODUCT((Calc!$A$2:$A$1001=$A10)*(Calc!$B$2:$B$1001="SALE")*(Calc!$I$2:$I$1001-Calc!$O$2:$O$1001)) | D10: =ROUND((MIN(MAX(Month!G10,0),Opening!C10)*Opening!D10+SUMPRODUCT((Calc!$A$2:$A$1001=$A10)*Calc!$G$2:$G$1001*(((Month!G10-(Opening!C10+Calc!$J$2:$J$1001))>0)*((Month!G10-(Opening!C10+Calc!$J$2:$J$1001))<Calc!$F$2:$F$1001)*(Month!G10-(Opening!C10+Calc!$J$2:$J$1001))+((Month!G10-(Opening!C10+Calc!$J$2:$J$1001))>=Calc!$F$2:$F$1001)*Calc!$F$2:$F$1001)))-(MIN(MAX(Month!J10,0),Opening!C10)*Opening!D10+SUMPRODUCT((Calc!$A$2:$A$1001=$A10)*Calc!$G$2:$G$1001*(((Month!J10-(Opening!C10+Calc!$J$2:$J$1001))>0)*((Month!J10-(Opening!C10+Calc!$J$2:$J$1001))<Calc!$F$2:$F$1001)*(Month!J10-(Opening!C10+Calc!$J$2:$J$1001))+((Month!J10-(Opening!C10+Calc!$J$2:$J$1001))>=Calc!$F$2:$F$1001)*Calc!$F$2:$F$1001))),2) | E10: =IF(B10<Opening!F10,"YES","NO") | F10: =IF(E10="YES",Opening!G10,0)
A11: =Opening!A11 | B11: =Month!G11-Month!J11 | C11: =SUMPRODUCT((Calc!$A$2:$A$1001=$A11)*(Calc!$B$2:$B$1001="SALE")*(Calc!$I$2:$I$1001-Calc!$O$2:$O$1001)) | D11: =ROUND((MIN(MAX(Month!G11,0),Opening!C11)*Opening!D11+SUMPRODUCT((Calc!$A$2:$A$1001=$A11)*Calc!$G$2:$G$1001*(((Month!G11-(Opening!C11+Calc!$J$2:$J$1001))>0)*((Month!G11-(Opening!C11+Calc!$J$2:$J$1001))<Calc!$F$2:$F$1001)*(Month!G11-(Opening!C11+Calc!$J$2:$J$1001))+((Month!G11-(Opening!C11+Calc!$J$2:$J$1001))>=Calc!$F$2:$F$1001)*Calc!$F$2:$F$1001)))-(MIN(MAX(Month!J11,0),Opening!C11)*Opening!D11+SUMPRODUCT((Calc!$A$2:$A$1001=$A11)*Calc!$G$2:$G$1001*(((Month!J11-(Opening!C11+Calc!$J$2:$J$1001))>0)*((Month!J11-(Opening!C11+Calc!$J$2:$J$1001))<Calc!$F$2:$F$1001)*(Month!J11-(Opening!C11+Calc!$J$2:$J$1001))+((Month!J11-(Opening!C11+Calc!$J$2:$J$1001))>=Calc!$F$2:$F$1001)*Calc!$F$2:$F$1001))),2) | E11: =IF(B11<Opening!F11,"YES","NO") | F11: =IF(E11="YES",Opening!G11,0)
A12: =Opening!A12 | B12: =Month!G12-Month!J12 | C12: =SUMPRODUCT((Calc!$A$2:$A$1001=$A12)*(Calc!$B$2:$B$1001="SALE")*(Calc!$I$2:$I$1001-Calc!$O$2:$O$1001)) | D12: =ROUND((MIN(MAX(Month!G12,0),Opening!C12)*Opening!D12+SUMPRODUCT((Calc!$A$2:$A$1001=$A12)*Calc!$G$2:$G$1001*(((Month!G12-(Opening!C12+Calc!$J$2:$J$1001))>0)*((Month!G12-(Opening!C12+Calc!$J$2:$J$1001))<Calc!$F$2:$F$1001)*(Month!G12-(Opening!C12+Calc!$J$2:$J$1001))+((Month!G12-(Opening!C12+Calc!$J$2:$J$1001))>=Calc!$F$2:$F$1001)*Calc!$F$2:$F$1001)))-(MIN(MAX(Month!J12,0),Opening!C12)*Opening!D12+SUMPRODUCT((Calc!$A$2:$A$1001=$A12)*Calc!$G$2:$G$1001*(((Month!J12-(Opening!C12+Calc!$J$2:$J$1001))>0)*((Month!J12-(Opening!C12+Calc!$J$2:$J$1001))<Calc!$F$2:$F$1001)*(Month!J12-(Opening!C12+Calc!$J$2:$J$1001))+((Month!J12-(Opening!C12+Calc!$J$2:$J$1001))>=Calc!$F$2:$F$1001)*Calc!$F$2:$F$1001))),2) | E12: =IF(B12<Opening!F12,"YES","NO") | F12: =IF(E12="YES",Opening!G12,0)
A13: =Opening!A13 | B13: =Month!G13-Month!J13 | C13: =SUMPRODUCT((Calc!$A$2:$A$1001=$A13)*(Calc!$B$2:$B$1001="SALE")*(Calc!$I$2:$I$1001-Calc!$O$2:$O$1001)) | D13: =ROUND((MIN(MAX(Month!G13,0),Opening!C13)*Opening!D13+SUMPRODUCT((Calc!$A$2:$A$1001=$A13)*Calc!$G$2:$G$1001*(((Month!G13-(Opening!C13+Calc!$J$2:$J$1001))>0)*((Month!G13-(Opening!C13+Calc!$J$2:$J$1001))<Calc!$F$2:$F$1001)*(Month!G13-(Opening!C13+Calc!$J$2:$J$1001))+((Month!G13-(Opening!C13+Calc!$J$2:$J$1001))>=Calc!$F$2:$F$1001)*Calc!$F$2:$F$1001)))-(MIN(MAX(Month!J13,0),Opening!C13)*Opening!D13+SUMPRODUCT((Calc!$A$2:$A$1001=$A13)*Calc!$G$2:$G$1001*(((Month!J13-(Opening!C13+Calc!$J$2:$J$1001))>0)*((Month!J13-(Opening!C13+Calc!$J$2:$J$1001))<Calc!$F$2:$F$1001)*(Month!J13-(Opening!C13+Calc!$J$2:$J$1001))+((Month!J13-(Opening!C13+Calc!$J$2:$J$1001))>=Calc!$F$2:$F$1001)*Calc!$F$2:$F$1001))),2) | E13: =IF(B13<Opening!F13,"YES","NO") | F13: =IF(E13="YES",Opening!G13,0)

Sheet Exceptions
A1: TxnID | B1: Why it was ignored
A2: =IFERROR(INDEX(Transactions!$A:$A,SMALL(Calc!$V$2:$V$1001,1)),"") | B2: =IF(A2="","",IF(COUNTIF(Transactions!$A$1:INDEX(Transactions!$A:$A,SMALL(Calc!$V$2:$V$1001,1)-1),A2)>0,"duplicate transaction id","return of a product never sold"))
A3: =IFERROR(INDEX(Transactions!$A:$A,SMALL(Calc!$V$2:$V$1001,2)),"") | B3: =IF(A3="","",IF(COUNTIF(Transactions!$A$1:INDEX(Transactions!$A:$A,SMALL(Calc!$V$2:$V$1001,2)-1),A3)>0,"duplicate transaction id","return of a product never sold"))
A4: =IFERROR(INDEX(Transactions!$A:$A,SMALL(Calc!$V$2:$V$1001,3)),"") | B4: =IF(A4="","",IF(COUNTIF(Transactions!$A$1:INDEX(Transactions!$A:$A,SMALL(Calc!$V$2:$V$1001,3)-1),A4)>0,"duplicate transaction id","return of a product never sold"))
A5: =IFERROR(INDEX(Transactions!$A:$A,SMALL(Calc!$V$2:$V$1001,4)),"") | B5: =IF(A5="","",IF(COUNTIF(Transactions!$A$1:INDEX(Transactions!$A:$A,SMALL(Calc!$V$2:$V$1001,4)-1),A5)>0,"duplicate transaction id","return of a product never sold"))
A6: =IFERROR(INDEX(Transactions!$A:$A,SMALL(Calc!$V$2:$V$1001,5)),"") | B6: =IF(A6="","",IF(COUNTIF(Transactions!$A$1:INDEX(Transactions!$A:$A,SMALL(Calc!$V$2:$V$1001,5)-1),A6)>0,"duplicate transaction id","return of a product never sold"))
